{
 "cells": [
  {
   "cell_type": "markdown",
   "metadata": {},
   "source": [
    "# Converting `NetCDF` datasets to `GeoTiff`"
   ]
  },
  {
   "cell_type": "markdown",
   "metadata": {},
   "source": [
    "<a id='libraries'></a>\n",
    "## Python libraries"
   ]
  },
  {
   "cell_type": "code",
   "execution_count": 1,
   "metadata": {},
   "outputs": [],
   "source": [
    "import numpy as np\n",
    "import rioxarray\n",
    "import xarray as xr\n",
    "from google.cloud import storage"
   ]
  },
  {
   "cell_type": "code",
   "execution_count": 2,
   "metadata": {},
   "outputs": [],
   "source": [
    "import os\n",
    "from dotenv import load_dotenv\n",
    "load_dotenv()\n",
    "from pathlib import Path \n",
    "env_path = Path('.') / '.env'"
   ]
  },
  {
   "cell_type": "markdown",
   "metadata": {},
   "source": [
    "<a id='utils'></a>\n",
    "## Utils"
   ]
  },
  {
   "cell_type": "code",
   "execution_count": 3,
   "metadata": {},
   "outputs": [],
   "source": [
    "def upload_blob(bucket_name, source_file_name, destination_blob_name, privatekey_path):\n",
    "    \"\"\"Uploads a file to the bucket.\"\"\"\n",
    "    # bucket_name = \"your-bucket-name\"\n",
    "    # source_file_name = \"local/path/to/file\"\n",
    "    # destination_blob_name = \"storage-object-name\"\n",
    "\n",
    "    storage_client = storage.Client.from_service_account_json(privatekey_path)\n",
    "    bucket = storage_client.bucket(bucket_name)\n",
    "    blob = bucket.blob(destination_blob_name)\n",
    "\n",
    "    blob.upload_from_filename(source_file_name)\n",
    "\n",
    "    print(\n",
    "        \"File {} uploaded to {}.\".format(\n",
    "            source_file_name, destination_blob_name\n",
    "        )\n",
    "    )"
   ]
  },
  {
   "cell_type": "code",
   "execution_count": 4,
   "metadata": {},
   "outputs": [],
   "source": [
    "def from_NetCDF_to_GeoTIFF(years):\n",
    "    for year in years:\n",
    "        print(f'Year: {year}')\n",
    "        # Read NetCDF\n",
    "        print(f'Reading NetCDF')\n",
    "        if int(year) <= 2015:\n",
    "            input_file_path = f'../data/dataset-satellite-land-cover/ESACCI-LC-L4-LCCS-Map-300m-P1Y-{year}-v2.0.7cds.nc'\n",
    "        else:\n",
    "            input_file_path = f'../data/dataset-satellite-land-cover/C3S-LC-L4-LCCS-Map-300m-P1Y-{year}-v2.1.1.nc'\n",
    "            \n",
    "        xds = xr.open_dataset(input_file_path)\n",
    "        \n",
    "        # Save GeoTIFF\n",
    "        print(f'Saving GeoTIFF')\n",
    "        output_file_path = f'../data/dataset-satellite-land-cover/ESA_{year}_ipcc.tif'\n",
    "        data = xds[\"lccs_class\"]\n",
    "        data.rio.set_spatial_dims(x_dim='lon', y_dim='lat', inplace=True)\n",
    "        data.rio.set_crs(\"epsg:4326\", inplace=True)\n",
    "        data.rio.to_raster(output_file_path)\n",
    "        \n",
    "        # Upload GeoTIFF to Google cloud storage\n",
    "        print(f'Uploading GeoTIFF to Google cloud storage')\n",
    "        bucket_name = 'vizz-data-transfer'\n",
    "        destination_blob_name = f'land-cover/ESA_{year}_ipcc.tif'\n",
    "\n",
    "        upload_blob(bucket_name, output_file_path, destination_blob_name, os.getenv(\"PRIVATEKEY_PATH\") )\n",
    "        \n",
    "        # Remove source file\n",
    "        os.remove(output_file_path)      "
   ]
  },
  {
   "cell_type": "markdown",
   "metadata": {},
   "source": [
    "## From `NetCDF` to `GeoTIFF` in Google cloud storage "
   ]
  },
  {
   "cell_type": "markdown",
   "metadata": {},
   "source": [
    "<a id='read_data'></a>\n",
    "### Read `NetCDF`"
   ]
  },
  {
   "cell_type": "code",
   "execution_count": 5,
   "metadata": {},
   "outputs": [
    {
     "data": {
      "text/html": [
       "<div><svg style=\"position: absolute; width: 0; height: 0; overflow: hidden\">\n",
       "<defs>\n",
       "<symbol id=\"icon-database\" viewBox=\"0 0 32 32\">\n",
       "<title>Show/Hide data repr</title>\n",
       "<path d=\"M16 0c-8.837 0-16 2.239-16 5v4c0 2.761 7.163 5 16 5s16-2.239 16-5v-4c0-2.761-7.163-5-16-5z\"></path>\n",
       "<path d=\"M16 17c-8.837 0-16-2.239-16-5v6c0 2.761 7.163 5 16 5s16-2.239 16-5v-6c0 2.761-7.163 5-16 5z\"></path>\n",
       "<path d=\"M16 26c-8.837 0-16-2.239-16-5v6c0 2.761 7.163 5 16 5s16-2.239 16-5v-6c0 2.761-7.163 5-16 5z\"></path>\n",
       "</symbol>\n",
       "<symbol id=\"icon-file-text2\" viewBox=\"0 0 32 32\">\n",
       "<title>Show/Hide attributes</title>\n",
       "<path d=\"M28.681 7.159c-0.694-0.947-1.662-2.053-2.724-3.116s-2.169-2.030-3.116-2.724c-1.612-1.182-2.393-1.319-2.841-1.319h-15.5c-1.378 0-2.5 1.121-2.5 2.5v27c0 1.378 1.122 2.5 2.5 2.5h23c1.378 0 2.5-1.122 2.5-2.5v-19.5c0-0.448-0.137-1.23-1.319-2.841zM24.543 5.457c0.959 0.959 1.712 1.825 2.268 2.543h-4.811v-4.811c0.718 0.556 1.584 1.309 2.543 2.268zM28 29.5c0 0.271-0.229 0.5-0.5 0.5h-23c-0.271 0-0.5-0.229-0.5-0.5v-27c0-0.271 0.229-0.5 0.5-0.5 0 0 15.499-0 15.5 0v7c0 0.552 0.448 1 1 1h7v19.5z\"></path>\n",
       "<path d=\"M23 26h-14c-0.552 0-1-0.448-1-1s0.448-1 1-1h14c0.552 0 1 0.448 1 1s-0.448 1-1 1z\"></path>\n",
       "<path d=\"M23 22h-14c-0.552 0-1-0.448-1-1s0.448-1 1-1h14c0.552 0 1 0.448 1 1s-0.448 1-1 1z\"></path>\n",
       "<path d=\"M23 18h-14c-0.552 0-1-0.448-1-1s0.448-1 1-1h14c0.552 0 1 0.448 1 1s-0.448 1-1 1z\"></path>\n",
       "</symbol>\n",
       "</defs>\n",
       "</svg>\n",
       "<style>/* CSS stylesheet for displaying xarray objects in jupyterlab.\n",
       " *\n",
       " */\n",
       "\n",
       ":root {\n",
       "  --xr-font-color0: var(--jp-content-font-color0, rgba(0, 0, 0, 1));\n",
       "  --xr-font-color2: var(--jp-content-font-color2, rgba(0, 0, 0, 0.54));\n",
       "  --xr-font-color3: var(--jp-content-font-color3, rgba(0, 0, 0, 0.38));\n",
       "  --xr-border-color: var(--jp-border-color2, #e0e0e0);\n",
       "  --xr-disabled-color: var(--jp-layout-color3, #bdbdbd);\n",
       "  --xr-background-color: var(--jp-layout-color0, white);\n",
       "  --xr-background-color-row-even: var(--jp-layout-color1, white);\n",
       "  --xr-background-color-row-odd: var(--jp-layout-color2, #eeeeee);\n",
       "}\n",
       "\n",
       ".xr-wrap {\n",
       "  min-width: 300px;\n",
       "  max-width: 700px;\n",
       "}\n",
       "\n",
       ".xr-header {\n",
       "  padding-top: 6px;\n",
       "  padding-bottom: 6px;\n",
       "  margin-bottom: 4px;\n",
       "  border-bottom: solid 1px var(--xr-border-color);\n",
       "}\n",
       "\n",
       ".xr-header > div,\n",
       ".xr-header > ul {\n",
       "  display: inline;\n",
       "  margin-top: 0;\n",
       "  margin-bottom: 0;\n",
       "}\n",
       "\n",
       ".xr-obj-type,\n",
       ".xr-array-name {\n",
       "  margin-left: 2px;\n",
       "  margin-right: 10px;\n",
       "}\n",
       "\n",
       ".xr-obj-type {\n",
       "  color: var(--xr-font-color2);\n",
       "}\n",
       "\n",
       ".xr-sections {\n",
       "  padding-left: 0 !important;\n",
       "  display: grid;\n",
       "  grid-template-columns: 150px auto auto 1fr 20px 20px;\n",
       "}\n",
       "\n",
       ".xr-section-item {\n",
       "  display: contents;\n",
       "}\n",
       "\n",
       ".xr-section-item input {\n",
       "  display: none;\n",
       "}\n",
       "\n",
       ".xr-section-item input + label {\n",
       "  color: var(--xr-disabled-color);\n",
       "}\n",
       "\n",
       ".xr-section-item input:enabled + label {\n",
       "  cursor: pointer;\n",
       "  color: var(--xr-font-color2);\n",
       "}\n",
       "\n",
       ".xr-section-item input:enabled + label:hover {\n",
       "  color: var(--xr-font-color0);\n",
       "}\n",
       "\n",
       ".xr-section-summary {\n",
       "  grid-column: 1;\n",
       "  color: var(--xr-font-color2);\n",
       "  font-weight: 500;\n",
       "}\n",
       "\n",
       ".xr-section-summary > span {\n",
       "  display: inline-block;\n",
       "  padding-left: 0.5em;\n",
       "}\n",
       "\n",
       ".xr-section-summary-in:disabled + label {\n",
       "  color: var(--xr-font-color2);\n",
       "}\n",
       "\n",
       ".xr-section-summary-in + label:before {\n",
       "  display: inline-block;\n",
       "  content: '►';\n",
       "  font-size: 11px;\n",
       "  width: 15px;\n",
       "  text-align: center;\n",
       "}\n",
       "\n",
       ".xr-section-summary-in:disabled + label:before {\n",
       "  color: var(--xr-disabled-color);\n",
       "}\n",
       "\n",
       ".xr-section-summary-in:checked + label:before {\n",
       "  content: '▼';\n",
       "}\n",
       "\n",
       ".xr-section-summary-in:checked + label > span {\n",
       "  display: none;\n",
       "}\n",
       "\n",
       ".xr-section-summary,\n",
       ".xr-section-inline-details {\n",
       "  padding-top: 4px;\n",
       "  padding-bottom: 4px;\n",
       "}\n",
       "\n",
       ".xr-section-inline-details {\n",
       "  grid-column: 2 / -1;\n",
       "}\n",
       "\n",
       ".xr-section-details {\n",
       "  display: none;\n",
       "  grid-column: 1 / -1;\n",
       "  margin-bottom: 5px;\n",
       "}\n",
       "\n",
       ".xr-section-summary-in:checked ~ .xr-section-details {\n",
       "  display: contents;\n",
       "}\n",
       "\n",
       ".xr-array-wrap {\n",
       "  grid-column: 1 / -1;\n",
       "  display: grid;\n",
       "  grid-template-columns: 20px auto;\n",
       "}\n",
       "\n",
       ".xr-array-wrap > label {\n",
       "  grid-column: 1;\n",
       "  vertical-align: top;\n",
       "}\n",
       "\n",
       ".xr-preview {\n",
       "  color: var(--xr-font-color3);\n",
       "}\n",
       "\n",
       ".xr-array-preview,\n",
       ".xr-array-data {\n",
       "  padding: 0 5px !important;\n",
       "  grid-column: 2;\n",
       "}\n",
       "\n",
       ".xr-array-data,\n",
       ".xr-array-in:checked ~ .xr-array-preview {\n",
       "  display: none;\n",
       "}\n",
       "\n",
       ".xr-array-in:checked ~ .xr-array-data,\n",
       ".xr-array-preview {\n",
       "  display: inline-block;\n",
       "}\n",
       "\n",
       ".xr-dim-list {\n",
       "  display: inline-block !important;\n",
       "  list-style: none;\n",
       "  padding: 0 !important;\n",
       "  margin: 0;\n",
       "}\n",
       "\n",
       ".xr-dim-list li {\n",
       "  display: inline-block;\n",
       "  padding: 0;\n",
       "  margin: 0;\n",
       "}\n",
       "\n",
       ".xr-dim-list:before {\n",
       "  content: '(';\n",
       "}\n",
       "\n",
       ".xr-dim-list:after {\n",
       "  content: ')';\n",
       "}\n",
       "\n",
       ".xr-dim-list li:not(:last-child):after {\n",
       "  content: ',';\n",
       "  padding-right: 5px;\n",
       "}\n",
       "\n",
       ".xr-has-index {\n",
       "  font-weight: bold;\n",
       "}\n",
       "\n",
       ".xr-var-list,\n",
       ".xr-var-item {\n",
       "  display: contents;\n",
       "}\n",
       "\n",
       ".xr-var-item > div,\n",
       ".xr-var-item label,\n",
       ".xr-var-item > .xr-var-name span {\n",
       "  background-color: var(--xr-background-color-row-even);\n",
       "  margin-bottom: 0;\n",
       "}\n",
       "\n",
       ".xr-var-item > .xr-var-name:hover span {\n",
       "  padding-right: 5px;\n",
       "}\n",
       "\n",
       ".xr-var-list > li:nth-child(odd) > div,\n",
       ".xr-var-list > li:nth-child(odd) > label,\n",
       ".xr-var-list > li:nth-child(odd) > .xr-var-name span {\n",
       "  background-color: var(--xr-background-color-row-odd);\n",
       "}\n",
       "\n",
       ".xr-var-name {\n",
       "  grid-column: 1;\n",
       "}\n",
       "\n",
       ".xr-var-dims {\n",
       "  grid-column: 2;\n",
       "}\n",
       "\n",
       ".xr-var-dtype {\n",
       "  grid-column: 3;\n",
       "  text-align: right;\n",
       "  color: var(--xr-font-color2);\n",
       "}\n",
       "\n",
       ".xr-var-preview {\n",
       "  grid-column: 4;\n",
       "}\n",
       "\n",
       ".xr-var-name,\n",
       ".xr-var-dims,\n",
       ".xr-var-dtype,\n",
       ".xr-preview,\n",
       ".xr-attrs dt {\n",
       "  white-space: nowrap;\n",
       "  overflow: hidden;\n",
       "  text-overflow: ellipsis;\n",
       "  padding-right: 10px;\n",
       "}\n",
       "\n",
       ".xr-var-name:hover,\n",
       ".xr-var-dims:hover,\n",
       ".xr-var-dtype:hover,\n",
       ".xr-attrs dt:hover {\n",
       "  overflow: visible;\n",
       "  width: auto;\n",
       "  z-index: 1;\n",
       "}\n",
       "\n",
       ".xr-var-attrs,\n",
       ".xr-var-data {\n",
       "  display: none;\n",
       "  background-color: var(--xr-background-color) !important;\n",
       "  padding-bottom: 5px !important;\n",
       "}\n",
       "\n",
       ".xr-var-attrs-in:checked ~ .xr-var-attrs,\n",
       ".xr-var-data-in:checked ~ .xr-var-data {\n",
       "  display: block;\n",
       "}\n",
       "\n",
       ".xr-var-data > table {\n",
       "  float: right;\n",
       "}\n",
       "\n",
       ".xr-var-name span,\n",
       ".xr-var-data,\n",
       ".xr-attrs {\n",
       "  padding-left: 25px !important;\n",
       "}\n",
       "\n",
       ".xr-attrs,\n",
       ".xr-var-attrs,\n",
       ".xr-var-data {\n",
       "  grid-column: 1 / -1;\n",
       "}\n",
       "\n",
       "dl.xr-attrs {\n",
       "  padding: 0;\n",
       "  margin: 0;\n",
       "  display: grid;\n",
       "  grid-template-columns: 125px auto;\n",
       "}\n",
       "\n",
       ".xr-attrs dt, dd {\n",
       "  padding: 0;\n",
       "  margin: 0;\n",
       "  float: left;\n",
       "  padding-right: 10px;\n",
       "  width: auto;\n",
       "}\n",
       "\n",
       ".xr-attrs dt {\n",
       "  font-weight: normal;\n",
       "  grid-column: 1;\n",
       "}\n",
       "\n",
       ".xr-attrs dt:hover span {\n",
       "  display: inline-block;\n",
       "  background: var(--xr-background-color);\n",
       "  padding-right: 10px;\n",
       "}\n",
       "\n",
       ".xr-attrs dd {\n",
       "  grid-column: 2;\n",
       "  white-space: pre-wrap;\n",
       "  word-break: break-all;\n",
       "}\n",
       "\n",
       ".xr-icon-database,\n",
       ".xr-icon-file-text2 {\n",
       "  display: inline-block;\n",
       "  vertical-align: middle;\n",
       "  width: 1em;\n",
       "  height: 1.5em !important;\n",
       "  stroke-width: 0;\n",
       "  stroke: currentColor;\n",
       "  fill: currentColor;\n",
       "}\n",
       "</style><div class='xr-wrap'><div class='xr-header'><div class='xr-obj-type'>xarray.Dataset</div></div><ul class='xr-sections'><li class='xr-section-item'><input id='section-cf857830-4cf4-4988-9327-a62fc7d56a46' class='xr-section-summary-in' type='checkbox' disabled ><label for='section-cf857830-4cf4-4988-9327-a62fc7d56a46' class='xr-section-summary'  title='Expand/collapse section'>Dimensions:</label><div class='xr-section-inline-details'><ul class='xr-dim-list'><li><span>bounds</span>: 2</li><li><span class='xr-has-index'>lat</span>: 64800</li><li><span class='xr-has-index'>lon</span>: 129600</li><li><span class='xr-has-index'>time</span>: 1</li></ul></div><div class='xr-section-details'></div></li><li class='xr-section-item'><input id='section-344c60fd-939a-4a30-9269-3ef01e7a1551' class='xr-section-summary-in' type='checkbox'  checked><label for='section-344c60fd-939a-4a30-9269-3ef01e7a1551' class='xr-section-summary' >Coordinates: <span>(3)</span></label><div class='xr-section-inline-details'></div><div class='xr-section-details'><ul class='xr-var-list'><li class='xr-var-item'><div class='xr-var-name'><span class='xr-has-index'>lat</span></div><div class='xr-var-dims'>(lat)</div><div class='xr-var-dtype'>float64</div><div class='xr-var-preview xr-preview'>90.0 90.0 89.99 ... -90.0 -90.0</div><input id='attrs-6704e8c2-43c6-4078-b1d1-f189b5f6730e' class='xr-var-attrs-in' type='checkbox' ><label for='attrs-6704e8c2-43c6-4078-b1d1-f189b5f6730e' title='Show/Hide attributes'><svg class='icon xr-icon-file-text2'><use xlink:href='#icon-file-text2'></use></svg></label><input id='data-aa51285d-65b3-447e-ad9a-e427ea36bc5c' class='xr-var-data-in' type='checkbox'><label for='data-aa51285d-65b3-447e-ad9a-e427ea36bc5c' title='Show/Hide data repr'><svg class='icon xr-icon-database'><use xlink:href='#icon-database'></use></svg></label><div class='xr-var-attrs'><dl class='xr-attrs'><dt><span>units :</span></dt><dd>degrees_north</dd><dt><span>long_name :</span></dt><dd>latitude</dd><dt><span>standard_name :</span></dt><dd>latitude</dd><dt><span>valid_min :</span></dt><dd>-90.0</dd><dt><span>valid_max :</span></dt><dd>90.0</dd><dt><span>bounds :</span></dt><dd>lat_bounds</dd><dt><span>axis :</span></dt><dd>Y</dd></dl></div><pre class='xr-var-data'>array([ 89.998611,  89.995833,  89.993056, ..., -89.993056, -89.995833,\n",
       "       -89.998611])</pre></li><li class='xr-var-item'><div class='xr-var-name'><span class='xr-has-index'>lon</span></div><div class='xr-var-dims'>(lon)</div><div class='xr-var-dtype'>float64</div><div class='xr-var-preview xr-preview'>-180.0 -180.0 ... 180.0 180.0</div><input id='attrs-98300e2e-529f-4ddb-b8b9-cafb6a0262e8' class='xr-var-attrs-in' type='checkbox' ><label for='attrs-98300e2e-529f-4ddb-b8b9-cafb6a0262e8' title='Show/Hide attributes'><svg class='icon xr-icon-file-text2'><use xlink:href='#icon-file-text2'></use></svg></label><input id='data-9a1927db-983c-43e8-b346-2d8b6f1e3ed0' class='xr-var-data-in' type='checkbox'><label for='data-9a1927db-983c-43e8-b346-2d8b6f1e3ed0' title='Show/Hide data repr'><svg class='icon xr-icon-database'><use xlink:href='#icon-database'></use></svg></label><div class='xr-var-attrs'><dl class='xr-attrs'><dt><span>units :</span></dt><dd>degrees_east</dd><dt><span>long_name :</span></dt><dd>longitude</dd><dt><span>standard_name :</span></dt><dd>longitude</dd><dt><span>valid_min :</span></dt><dd>-180.0</dd><dt><span>valid_max :</span></dt><dd>180.0</dd><dt><span>bounds :</span></dt><dd>lon_bounds</dd><dt><span>axis :</span></dt><dd>X</dd></dl></div><pre class='xr-var-data'>array([-179.998611, -179.995833, -179.993056, ...,  179.993056,  179.995833,\n",
       "        179.998611])</pre></li><li class='xr-var-item'><div class='xr-var-name'><span class='xr-has-index'>time</span></div><div class='xr-var-dims'>(time)</div><div class='xr-var-dtype'>datetime64[ns]</div><div class='xr-var-preview xr-preview'>2017-01-01</div><input id='attrs-58a704c4-3773-4732-948a-eda2bdde51ff' class='xr-var-attrs-in' type='checkbox' ><label for='attrs-58a704c4-3773-4732-948a-eda2bdde51ff' title='Show/Hide attributes'><svg class='icon xr-icon-file-text2'><use xlink:href='#icon-file-text2'></use></svg></label><input id='data-ecfdb29a-8976-4539-83fc-df24a84c1b72' class='xr-var-data-in' type='checkbox'><label for='data-ecfdb29a-8976-4539-83fc-df24a84c1b72' title='Show/Hide data repr'><svg class='icon xr-icon-database'><use xlink:href='#icon-database'></use></svg></label><div class='xr-var-attrs'><dl class='xr-attrs'><dt><span>standard_name :</span></dt><dd>time</dd><dt><span>long_name :</span></dt><dd>time</dd><dt><span>axis :</span></dt><dd>T</dd><dt><span>bounds :</span></dt><dd>time_bounds</dd></dl></div><pre class='xr-var-data'>array([&#x27;2017-01-01T00:00:00.000000000&#x27;], dtype=&#x27;datetime64[ns]&#x27;)</pre></li></ul></div></li><li class='xr-section-item'><input id='section-1cba329c-c9c5-4bbc-a7e4-2250f73bdf20' class='xr-section-summary-in' type='checkbox'  checked><label for='section-1cba329c-c9c5-4bbc-a7e4-2250f73bdf20' class='xr-section-summary' >Data variables: <span>(9)</span></label><div class='xr-section-inline-details'></div><div class='xr-section-details'><ul class='xr-var-list'><li class='xr-var-item'><div class='xr-var-name'><span>lccs_class</span></div><div class='xr-var-dims'>(time, lat, lon)</div><div class='xr-var-dtype'>uint8</div><div class='xr-var-preview xr-preview'>...</div><input id='attrs-cfb9c1e0-7d0d-41d4-8e95-0a34a915414f' class='xr-var-attrs-in' type='checkbox' ><label for='attrs-cfb9c1e0-7d0d-41d4-8e95-0a34a915414f' title='Show/Hide attributes'><svg class='icon xr-icon-file-text2'><use xlink:href='#icon-file-text2'></use></svg></label><input id='data-741df3ed-d03f-4bda-ac0d-dae45ca1746c' class='xr-var-data-in' type='checkbox'><label for='data-741df3ed-d03f-4bda-ac0d-dae45ca1746c' title='Show/Hide data repr'><svg class='icon xr-icon-database'><use xlink:href='#icon-database'></use></svg></label><div class='xr-var-attrs'><dl class='xr-attrs'><dt><span>standard_name :</span></dt><dd>land_cover_lccs</dd><dt><span>flag_colors :</span></dt><dd>#ffff64 #ffff64 #ffff00 #aaf0f0 #dcf064 #c8c864 #006400 #00a000 #00a000 #aac800 #003c00 #003c00 #005000 #285000 #285000 #286400 #788200 #8ca000 #be9600 #966400 #966400 #966400 #ffb432 #ffdcd2 #ffebaf #ffc864 #ffd278 #ffebaf #00785a #009678 #00dc82 #c31400 #fff5d7 #dcdcdc #fff5d7 #0046c8 #ffffff</dd><dt><span>long_name :</span></dt><dd>Land cover class defined in LCCS</dd><dt><span>valid_min :</span></dt><dd>1</dd><dt><span>valid_max :</span></dt><dd>220</dd><dt><span>ancillary_variables :</span></dt><dd>processed_flag current_pixel_state observation_count change_count</dd><dt><span>flag_meanings :</span></dt><dd>no_data cropland_rainfed cropland_rainfed_herbaceous_cover cropland_rainfed_tree_or_shrub_cover cropland_irrigated mosaic_cropland mosaic_natural_vegetation tree_broadleaved_evergreen_closed_to_open tree_broadleaved_deciduous_closed_to_open tree_broadleaved_deciduous_closed tree_broadleaved_deciduous_open tree_needleleaved_evergreen_closed_to_open tree_needleleaved_evergreen_closed tree_needleleaved_evergreen_open tree_needleleaved_deciduous_closed_to_open tree_needleleaved_deciduous_closed tree_needleleaved_deciduous_open tree_mixed mosaic_tree_and_shrub mosaic_herbaceous shrubland shrubland_evergreen shrubland_deciduous grassland lichens_and_mosses sparse_vegetation sparse_tree sparse_shrub sparse_herbaceous tree_cover_flooded_fresh_or_brakish_water tree_cover_flooded_saline_water shrub_or_herbaceous_cover_flooded urban bare_areas bare_areas_consolidated bare_areas_unconsolidated water snow_and_ice</dd><dt><span>flag_values :</span></dt><dd>[  0  10  11  12  20  30  40  50  60  61  62  70  71  72  80  81  82  90\n",
       " 100 110 120 121 122 130 140 150 151 152 153 160 170 180 190 200 201 202\n",
       " 210 220]</dd></dl></div><pre class='xr-var-data'>[8398080000 values with dtype=uint8]</pre></li><li class='xr-var-item'><div class='xr-var-name'><span>processed_flag</span></div><div class='xr-var-dims'>(time, lat, lon)</div><div class='xr-var-dtype'>float32</div><div class='xr-var-preview xr-preview'>...</div><input id='attrs-586fc3e0-0503-422f-afd0-bdf9bc598edc' class='xr-var-attrs-in' type='checkbox' ><label for='attrs-586fc3e0-0503-422f-afd0-bdf9bc598edc' title='Show/Hide attributes'><svg class='icon xr-icon-file-text2'><use xlink:href='#icon-file-text2'></use></svg></label><input id='data-e455a9e3-b31e-46ef-8b63-412b2ebd2d1d' class='xr-var-data-in' type='checkbox'><label for='data-e455a9e3-b31e-46ef-8b63-412b2ebd2d1d' title='Show/Hide data repr'><svg class='icon xr-icon-database'><use xlink:href='#icon-database'></use></svg></label><div class='xr-var-attrs'><dl class='xr-attrs'><dt><span>long_name :</span></dt><dd>LC map processed area flag</dd><dt><span>standard_name :</span></dt><dd>land_cover_lccs status_flag</dd><dt><span>valid_min :</span></dt><dd>0</dd><dt><span>valid_max :</span></dt><dd>1</dd><dt><span>flag_meanings :</span></dt><dd>not_processed processed</dd><dt><span>flag_values :</span></dt><dd>[0 1]</dd></dl></div><pre class='xr-var-data'>[8398080000 values with dtype=float32]</pre></li><li class='xr-var-item'><div class='xr-var-name'><span>current_pixel_state</span></div><div class='xr-var-dims'>(time, lat, lon)</div><div class='xr-var-dtype'>float32</div><div class='xr-var-preview xr-preview'>...</div><input id='attrs-81f42b94-0cce-41e6-a1b4-b2877cf215de' class='xr-var-attrs-in' type='checkbox' ><label for='attrs-81f42b94-0cce-41e6-a1b4-b2877cf215de' title='Show/Hide attributes'><svg class='icon xr-icon-file-text2'><use xlink:href='#icon-file-text2'></use></svg></label><input id='data-ea72d699-0a9c-4cc3-b341-a7efd14e1455' class='xr-var-data-in' type='checkbox'><label for='data-ea72d699-0a9c-4cc3-b341-a7efd14e1455' title='Show/Hide data repr'><svg class='icon xr-icon-database'><use xlink:href='#icon-database'></use></svg></label><div class='xr-var-attrs'><dl class='xr-attrs'><dt><span>long_name :</span></dt><dd>LC pixel type mask</dd><dt><span>standard_name :</span></dt><dd>land_cover_lccs status_flag</dd><dt><span>valid_min :</span></dt><dd>0</dd><dt><span>valid_max :</span></dt><dd>5</dd><dt><span>flag_meanings :</span></dt><dd>invalid clear_land clear_water clear_snow_ice cloud cloud_shadow</dd><dt><span>flag_values :</span></dt><dd>[0 1 2 3 4 5]</dd></dl></div><pre class='xr-var-data'>[8398080000 values with dtype=float32]</pre></li><li class='xr-var-item'><div class='xr-var-name'><span>observation_count</span></div><div class='xr-var-dims'>(time, lat, lon)</div><div class='xr-var-dtype'>uint16</div><div class='xr-var-preview xr-preview'>...</div><input id='attrs-a89bcc05-fd34-4c90-bc0c-ec523b089d5e' class='xr-var-attrs-in' type='checkbox' ><label for='attrs-a89bcc05-fd34-4c90-bc0c-ec523b089d5e' title='Show/Hide attributes'><svg class='icon xr-icon-file-text2'><use xlink:href='#icon-file-text2'></use></svg></label><input id='data-53d10dd5-b310-4b7a-92e9-d849727a3bb7' class='xr-var-data-in' type='checkbox'><label for='data-53d10dd5-b310-4b7a-92e9-d849727a3bb7' title='Show/Hide data repr'><svg class='icon xr-icon-database'><use xlink:href='#icon-database'></use></svg></label><div class='xr-var-attrs'><dl class='xr-attrs'><dt><span>long_name :</span></dt><dd>number of valid observations</dd><dt><span>standard_name :</span></dt><dd>land_cover_lccs number_of_observations</dd><dt><span>valid_min :</span></dt><dd>0</dd><dt><span>valid_max :</span></dt><dd>32767</dd></dl></div><pre class='xr-var-data'>[8398080000 values with dtype=uint16]</pre></li><li class='xr-var-item'><div class='xr-var-name'><span>change_count</span></div><div class='xr-var-dims'>(time, lat, lon)</div><div class='xr-var-dtype'>uint8</div><div class='xr-var-preview xr-preview'>...</div><input id='attrs-58783dfb-f6d9-4254-a919-fd821e9ed627' class='xr-var-attrs-in' type='checkbox' ><label for='attrs-58783dfb-f6d9-4254-a919-fd821e9ed627' title='Show/Hide attributes'><svg class='icon xr-icon-file-text2'><use xlink:href='#icon-file-text2'></use></svg></label><input id='data-3ab28909-11a5-49d6-9f91-5f2aef6c9358' class='xr-var-data-in' type='checkbox'><label for='data-3ab28909-11a5-49d6-9f91-5f2aef6c9358' title='Show/Hide data repr'><svg class='icon xr-icon-database'><use xlink:href='#icon-database'></use></svg></label><div class='xr-var-attrs'><dl class='xr-attrs'><dt><span>long_name :</span></dt><dd>number of class changes</dd><dt><span>valid_min :</span></dt><dd>0</dd><dt><span>valid_max :</span></dt><dd>100</dd></dl></div><pre class='xr-var-data'>[8398080000 values with dtype=uint8]</pre></li><li class='xr-var-item'><div class='xr-var-name'><span>crs</span></div><div class='xr-var-dims'>()</div><div class='xr-var-dtype'>int32</div><div class='xr-var-preview xr-preview'>...</div><input id='attrs-e4cc693f-65fc-400d-9348-28d8db8eea80' class='xr-var-attrs-in' type='checkbox' ><label for='attrs-e4cc693f-65fc-400d-9348-28d8db8eea80' title='Show/Hide attributes'><svg class='icon xr-icon-file-text2'><use xlink:href='#icon-file-text2'></use></svg></label><input id='data-caa2b8ff-0069-4107-80d6-cd0208cc105f' class='xr-var-data-in' type='checkbox'><label for='data-caa2b8ff-0069-4107-80d6-cd0208cc105f' title='Show/Hide data repr'><svg class='icon xr-icon-database'><use xlink:href='#icon-database'></use></svg></label><div class='xr-var-attrs'><dl class='xr-attrs'><dt><span>wkt :</span></dt><dd>GEOGCS[&quot;WGS 84&quot;, \n",
       "  DATUM[&quot;World Geodetic System 1984&quot;, \n",
       "    SPHEROID[&quot;WGS 84&quot;, 6378137.0, 298.257223563, AUTHORITY[&quot;EPSG&quot;,&quot;7030&quot;]], \n",
       "    AUTHORITY[&quot;EPSG&quot;,&quot;6326&quot;]], \n",
       "  PRIMEM[&quot;Greenwich&quot;, 0.0, AUTHORITY[&quot;EPSG&quot;,&quot;8901&quot;]], \n",
       "  UNIT[&quot;degree&quot;, 0.017453292519943295], \n",
       "  AXIS[&quot;Geodetic longitude&quot;, EAST], \n",
       "  AXIS[&quot;Geodetic latitude&quot;, NORTH], \n",
       "  AUTHORITY[&quot;EPSG&quot;,&quot;4326&quot;]]</dd><dt><span>i2m :</span></dt><dd>0.002777777777778,0.0,0.0,-0.002777777777778,-180.0,90.0</dd></dl></div><pre class='xr-var-data'>array(-2147483647, dtype=int32)</pre></li><li class='xr-var-item'><div class='xr-var-name'><span>lat_bounds</span></div><div class='xr-var-dims'>(lat, bounds)</div><div class='xr-var-dtype'>float64</div><div class='xr-var-preview xr-preview'>...</div><input id='attrs-7f402da5-c48b-4fa3-827d-70e7ea73680a' class='xr-var-attrs-in' type='checkbox' disabled><label for='attrs-7f402da5-c48b-4fa3-827d-70e7ea73680a' title='Show/Hide attributes'><svg class='icon xr-icon-file-text2'><use xlink:href='#icon-file-text2'></use></svg></label><input id='data-7916e67d-451f-494f-b7b3-b88a7bd391e6' class='xr-var-data-in' type='checkbox'><label for='data-7916e67d-451f-494f-b7b3-b88a7bd391e6' title='Show/Hide data repr'><svg class='icon xr-icon-database'><use xlink:href='#icon-database'></use></svg></label><div class='xr-var-attrs'><dl class='xr-attrs'></dl></div><pre class='xr-var-data'>[129600 values with dtype=float64]</pre></li><li class='xr-var-item'><div class='xr-var-name'><span>lon_bounds</span></div><div class='xr-var-dims'>(lon, bounds)</div><div class='xr-var-dtype'>float64</div><div class='xr-var-preview xr-preview'>...</div><input id='attrs-0fcdd19f-ef15-428d-8f4c-acf55ef09472' class='xr-var-attrs-in' type='checkbox' disabled><label for='attrs-0fcdd19f-ef15-428d-8f4c-acf55ef09472' title='Show/Hide attributes'><svg class='icon xr-icon-file-text2'><use xlink:href='#icon-file-text2'></use></svg></label><input id='data-8a228647-8204-4e76-b016-81a9da0f1e3c' class='xr-var-data-in' type='checkbox'><label for='data-8a228647-8204-4e76-b016-81a9da0f1e3c' title='Show/Hide data repr'><svg class='icon xr-icon-database'><use xlink:href='#icon-database'></use></svg></label><div class='xr-var-attrs'><dl class='xr-attrs'></dl></div><pre class='xr-var-data'>[259200 values with dtype=float64]</pre></li><li class='xr-var-item'><div class='xr-var-name'><span>time_bounds</span></div><div class='xr-var-dims'>(time, bounds)</div><div class='xr-var-dtype'>datetime64[ns]</div><div class='xr-var-preview xr-preview'>...</div><input id='attrs-689656c3-cb6c-428e-ae44-f35361772d77' class='xr-var-attrs-in' type='checkbox' disabled><label for='attrs-689656c3-cb6c-428e-ae44-f35361772d77' title='Show/Hide attributes'><svg class='icon xr-icon-file-text2'><use xlink:href='#icon-file-text2'></use></svg></label><input id='data-1a557c0a-9c05-43ad-b314-13b4b4fef73f' class='xr-var-data-in' type='checkbox'><label for='data-1a557c0a-9c05-43ad-b314-13b4b4fef73f' title='Show/Hide data repr'><svg class='icon xr-icon-database'><use xlink:href='#icon-database'></use></svg></label><div class='xr-var-attrs'><dl class='xr-attrs'></dl></div><pre class='xr-var-data'>array([[&#x27;2017-01-01T00:00:00.000000000&#x27;, &#x27;2017-12-31T00:00:00.000000000&#x27;]],\n",
       "      dtype=&#x27;datetime64[ns]&#x27;)</pre></li></ul></div></li><li class='xr-section-item'><input id='section-f8a92549-4f40-48f6-a90e-b7091eb07084' class='xr-section-summary-in' type='checkbox'  ><label for='section-f8a92549-4f40-48f6-a90e-b7091eb07084' class='xr-section-summary' >Attributes: <span>(38)</span></label><div class='xr-section-inline-details'></div><div class='xr-section-details'><dl class='xr-attrs'><dt><span>id :</span></dt><dd>C3S-LC-L4-LCCS-Map-300m-P1Y-2017-v2.1.1</dd><dt><span>title :</span></dt><dd>Land Cover Map of 2017</dd><dt><span>summary :</span></dt><dd>This dataset characterizes the land cover of a particular year (see time_coverage). The land cover was derived from the analysis of satellite data time series of the full period.</dd><dt><span>type :</span></dt><dd>C3S-LC-L4-LCCS-Map-300m-P1Y</dd><dt><span>project :</span></dt><dd>EC C3S Land cover</dd><dt><span>references :</span></dt><dd>https://cds.climate.copernicus.eu/</dd><dt><span>institution :</span></dt><dd>UCLouvain</dd><dt><span>contact :</span></dt><dd>copernicus-support@ecmwf.int</dd><dt><span>comment :</span></dt><dd></dd><dt><span>Conventions :</span></dt><dd>CF-1.6</dd><dt><span>standard_name_vocabulary :</span></dt><dd>NetCDF Climate and Forecast (CF) Standard Names version 21</dd><dt><span>keywords :</span></dt><dd>land cover classification,satellite,observation</dd><dt><span>keywords_vocabulary :</span></dt><dd>NASA Global Change Master Directory (GCMD) Science Keywords</dd><dt><span>license :</span></dt><dd>EC C3S Land cover Data Policy</dd><dt><span>naming_authority :</span></dt><dd></dd><dt><span>cdm_data_type :</span></dt><dd>grid</dd><dt><span>TileSize :</span></dt><dd>2025:2025</dd><dt><span>tracking_id :</span></dt><dd>79c7ccd3-b2ae-4aab-9391-dab1163da910</dd><dt><span>product_version :</span></dt><dd>2.1.1</dd><dt><span>creation_date :</span></dt><dd>20190131T133214Z</dd><dt><span>creator_name :</span></dt><dd>UCLouvain</dd><dt><span>creator_url :</span></dt><dd>http://www.uclouvain.be/</dd><dt><span>creator_email :</span></dt><dd>landcover-cci@uclouvain.be</dd><dt><span>source :</span></dt><dd>PROBA-V</dd><dt><span>history :</span></dt><dd>lc-sr-1.0, lc-classification-1.0,lc-user-tools-3.14,lc-user-tools-4.3</dd><dt><span>time_coverage_start :</span></dt><dd>20170101</dd><dt><span>time_coverage_end :</span></dt><dd>20171231</dd><dt><span>time_coverage_duration :</span></dt><dd>P1Y</dd><dt><span>time_coverage_resolution :</span></dt><dd>P1Y</dd><dt><span>geospatial_lat_min :</span></dt><dd>-90.0</dd><dt><span>geospatial_lat_max :</span></dt><dd>90.0</dd><dt><span>geospatial_lon_min :</span></dt><dd>null</dd><dt><span>geospatial_lon_max :</span></dt><dd>null</dd><dt><span>spatial_resolution :</span></dt><dd>300m</dd><dt><span>geospatial_lat_units :</span></dt><dd>degrees_north</dd><dt><span>geospatial_lat_resolution :</span></dt><dd>0.002778</dd><dt><span>geospatial_lon_units :</span></dt><dd>degrees_east</dd><dt><span>geospatial_lon_resolution :</span></dt><dd>0.002778</dd></dl></div></li></ul></div></div>"
      ],
      "text/plain": [
       "<xarray.Dataset>\n",
       "Dimensions:              (bounds: 2, lat: 64800, lon: 129600, time: 1)\n",
       "Coordinates:\n",
       "  * lat                  (lat) float64 90.0 90.0 89.99 ... -89.99 -90.0 -90.0\n",
       "  * lon                  (lon) float64 -180.0 -180.0 -180.0 ... 180.0 180.0\n",
       "  * time                 (time) datetime64[ns] 2017-01-01\n",
       "Dimensions without coordinates: bounds\n",
       "Data variables:\n",
       "    lccs_class           (time, lat, lon) uint8 ...\n",
       "    processed_flag       (time, lat, lon) float32 ...\n",
       "    current_pixel_state  (time, lat, lon) float32 ...\n",
       "    observation_count    (time, lat, lon) uint16 ...\n",
       "    change_count         (time, lat, lon) uint8 ...\n",
       "    crs                  int32 ...\n",
       "    lat_bounds           (lat, bounds) float64 ...\n",
       "    lon_bounds           (lon, bounds) float64 ...\n",
       "    time_bounds          (time, bounds) datetime64[ns] ...\n",
       "Attributes:\n",
       "    id:                         C3S-LC-L4-LCCS-Map-300m-P1Y-2017-v2.1.1\n",
       "    title:                      Land Cover Map of 2017\n",
       "    summary:                    This dataset characterizes the land cover of ...\n",
       "    type:                       C3S-LC-L4-LCCS-Map-300m-P1Y\n",
       "    project:                    EC C3S Land cover\n",
       "    references:                 https://cds.climate.copernicus.eu/\n",
       "    institution:                UCLouvain\n",
       "    contact:                    copernicus-support@ecmwf.int\n",
       "    comment:                    \n",
       "    Conventions:                CF-1.6\n",
       "    standard_name_vocabulary:   NetCDF Climate and Forecast (CF) Standard Nam...\n",
       "    keywords:                   land cover classification,satellite,observation\n",
       "    keywords_vocabulary:        NASA Global Change Master Directory (GCMD) Sc...\n",
       "    license:                    EC C3S Land cover Data Policy\n",
       "    naming_authority:           \n",
       "    cdm_data_type:              grid\n",
       "    TileSize:                   2025:2025\n",
       "    tracking_id:                79c7ccd3-b2ae-4aab-9391-dab1163da910\n",
       "    product_version:            2.1.1\n",
       "    creation_date:              20190131T133214Z\n",
       "    creator_name:               UCLouvain\n",
       "    creator_url:                http://www.uclouvain.be/\n",
       "    creator_email:              landcover-cci@uclouvain.be\n",
       "    source:                     PROBA-V\n",
       "    history:                    lc-sr-1.0, lc-classification-1.0,lc-user-tool...\n",
       "    time_coverage_start:        20170101\n",
       "    time_coverage_end:          20171231\n",
       "    time_coverage_duration:     P1Y\n",
       "    time_coverage_resolution:   P1Y\n",
       "    geospatial_lat_min:         -90.0\n",
       "    geospatial_lat_max:         90.0\n",
       "    geospatial_lon_min:         null\n",
       "    geospatial_lon_max:         null\n",
       "    spatial_resolution:         300m\n",
       "    geospatial_lat_units:       degrees_north\n",
       "    geospatial_lat_resolution:  0.002778\n",
       "    geospatial_lon_units:       degrees_east\n",
       "    geospatial_lon_resolution:  0.002778"
      ]
     },
     "execution_count": 5,
     "metadata": {},
     "output_type": "execute_result"
    }
   ],
   "source": [
    "year = '2017'\n",
    "xds = xr.open_dataset(f'../data/dataset-satellite-land-cover/C3S-LC-L4-LCCS-Map-300m-P1Y-{year}-v2.1.1.nc')\n",
    "xds"
   ]
  },
  {
   "cell_type": "code",
   "execution_count": 7,
   "metadata": {},
   "outputs": [
    {
     "data": {
      "text/plain": [
       "{'standard_name': 'land_cover_lccs',\n",
       " 'flag_colors': '#ffff64 #ffff64 #ffff00 #aaf0f0 #dcf064 #c8c864 #006400 #00a000 #00a000 #aac800 #003c00 #003c00 #005000 #285000 #285000 #286400 #788200 #8ca000 #be9600 #966400 #966400 #966400 #ffb432 #ffdcd2 #ffebaf #ffc864 #ffd278 #ffebaf #00785a #009678 #00dc82 #c31400 #fff5d7 #dcdcdc #fff5d7 #0046c8 #ffffff',\n",
       " 'long_name': 'Land cover class defined in LCCS',\n",
       " 'valid_min': 1,\n",
       " 'valid_max': 220,\n",
       " 'ancillary_variables': 'processed_flag current_pixel_state observation_count change_count',\n",
       " 'flag_meanings': 'no_data cropland_rainfed cropland_rainfed_herbaceous_cover cropland_rainfed_tree_or_shrub_cover cropland_irrigated mosaic_cropland mosaic_natural_vegetation tree_broadleaved_evergreen_closed_to_open tree_broadleaved_deciduous_closed_to_open tree_broadleaved_deciduous_closed tree_broadleaved_deciduous_open tree_needleleaved_evergreen_closed_to_open tree_needleleaved_evergreen_closed tree_needleleaved_evergreen_open tree_needleleaved_deciduous_closed_to_open tree_needleleaved_deciduous_closed tree_needleleaved_deciduous_open tree_mixed mosaic_tree_and_shrub mosaic_herbaceous shrubland shrubland_evergreen shrubland_deciduous grassland lichens_and_mosses sparse_vegetation sparse_tree sparse_shrub sparse_herbaceous tree_cover_flooded_fresh_or_brakish_water tree_cover_flooded_saline_water shrub_or_herbaceous_cover_flooded urban bare_areas bare_areas_consolidated bare_areas_unconsolidated water snow_and_ice',\n",
       " 'flag_values': array([  0,  10,  11,  12,  20,  30,  40,  50,  60,  61,  62,  70,  71,\n",
       "         72,  80,  81,  82,  90, 100, 110, 120, 121, 122, 130, 140, 150,\n",
       "        151, 152, 153, 160, 170, 180, 190, 200, 201, 202, 210, 220],\n",
       "       dtype=uint8)}"
      ]
     },
     "execution_count": 7,
     "metadata": {},
     "output_type": "execute_result"
    }
   ],
   "source": [
    "xds[\"lccs_class\"].attrs"
   ]
  },
  {
   "cell_type": "markdown",
   "metadata": {},
   "source": [
    "<a id='save_data'></a>\n",
    "### Save `GeoTIFF`"
   ]
  },
  {
   "cell_type": "code",
   "execution_count": null,
   "metadata": {},
   "outputs": [],
   "source": [
    "# Save GeoTIFF \n",
    "data = xds[\"lccs_class\"]\n",
    "data.rio.set_spatial_dims(x_dim='lon', y_dim='lat', inplace=True)\n",
    "data.rio.set_crs(\"epsg:4326\", inplace=True)\n",
    "data.rio.to_raster(f'../data/dataset-satellite-land-cover/ESA_{year}_ipcc.tif')"
   ]
  },
  {
   "cell_type": "markdown",
   "metadata": {},
   "source": [
    "### Upload `GeoTIFF` to Google cloud storage:"
   ]
  },
  {
   "cell_type": "code",
   "execution_count": null,
   "metadata": {},
   "outputs": [],
   "source": [
    "bucket_name = 'vizz-data-transfer'\n",
    "source_file_name = f'../data/dataset-satellite-land-cover/ESA_{year}_ipcc.tif'\n",
    "destination_blob_name = f'land-cover/ESA_{year}_ipcc.tif'\n",
    "\n",
    "upload_blob(bucket_name, source_file_name, destination_blob_name, os.getenv(\"PRIVATEKEY_PATH\") )"
   ]
  },
  {
   "cell_type": "markdown",
   "metadata": {},
   "source": [
    "### All together"
   ]
  },
  {
   "cell_type": "code",
   "execution_count": null,
   "metadata": {},
   "outputs": [],
   "source": [
    "years = np.arange(2016, 2018+1, 1).astype(np.str)\n",
    "from_NetCDF_to_GeoTIFF(years)"
   ]
  },
  {
   "cell_type": "markdown",
   "metadata": {},
   "source": [
    "<a id='export_data'></a>\n",
    "### Export `GeoTIFF` to Earth Engine"
   ]
  },
  {
   "cell_type": "code",
   "execution_count": 6,
   "metadata": {
    "collapsed": true,
    "jupyter": {
     "outputs_hidden": true
    }
   },
   "outputs": [
    {
     "name": "stdout",
     "output_type": "stream",
     "text": [
      "Running command using Cloud API.  Set --no-use_cloud_api to go back to using the API\n",
      "\n",
      "W0519 11:19:36.971474 140735859868544 __init__.py:44] file_cache is unavailable when using oauth2client >= 4.0.0 or google-auth\n",
      "Traceback (most recent call last):\n",
      "  File \"/Users/ikersanchez/anaconda3/lib/python3.7/site-packages/googleapiclient/discovery_cache/__init__.py\", line 36, in autodetect\n",
      "    from google.appengine.api import memcache\n",
      "ModuleNotFoundError: No module named 'google.appengine'\n",
      "\n",
      "During handling of the above exception, another exception occurred:\n",
      "\n",
      "Traceback (most recent call last):\n",
      "  File \"/Users/ikersanchez/anaconda3/lib/python3.7/site-packages/googleapiclient/discovery_cache/file_cache.py\", line 33, in <module>\n",
      "    from oauth2client.contrib.locked_file import LockedFile\n",
      "ModuleNotFoundError: No module named 'oauth2client'\n",
      "\n",
      "During handling of the above exception, another exception occurred:\n",
      "\n",
      "Traceback (most recent call last):\n",
      "  File \"/Users/ikersanchez/anaconda3/lib/python3.7/site-packages/googleapiclient/discovery_cache/file_cache.py\", line 37, in <module>\n",
      "    from oauth2client.locked_file import LockedFile\n",
      "ModuleNotFoundError: No module named 'oauth2client'\n",
      "\n",
      "During handling of the above exception, another exception occurred:\n",
      "\n",
      "Traceback (most recent call last):\n",
      "  File \"/Users/ikersanchez/anaconda3/lib/python3.7/site-packages/googleapiclient/discovery_cache/__init__.py\", line 41, in autodetect\n",
      "    from . import file_cache\n",
      "  File \"/Users/ikersanchez/anaconda3/lib/python3.7/site-packages/googleapiclient/discovery_cache/file_cache.py\", line 41, in <module>\n",
      "    'file_cache is unavailable when using oauth2client >= 4.0.0 or google-auth')\n",
      "ImportError: file_cache is unavailable when using oauth2client >= 4.0.0 or google-auth\n",
      "I0519 11:19:36.973526 140735859868544 discovery.py:271] URL being requested: GET https://earthengine.googleapis.com/$discovery/rest?version=v1alpha&prettyPrint=false\n",
      "W0519 11:19:37.896400 140735859868544 __init__.py:44] file_cache is unavailable when using oauth2client >= 4.0.0 or google-auth\n",
      "Traceback (most recent call last):\n",
      "  File \"/Users/ikersanchez/anaconda3/lib/python3.7/site-packages/googleapiclient/discovery_cache/__init__.py\", line 36, in autodetect\n",
      "    from google.appengine.api import memcache\n",
      "ModuleNotFoundError: No module named 'google.appengine'\n",
      "\n",
      "During handling of the above exception, another exception occurred:\n",
      "\n",
      "Traceback (most recent call last):\n",
      "  File \"/Users/ikersanchez/anaconda3/lib/python3.7/site-packages/googleapiclient/discovery_cache/file_cache.py\", line 33, in <module>\n",
      "    from oauth2client.contrib.locked_file import LockedFile\n",
      "ModuleNotFoundError: No module named 'oauth2client'\n",
      "\n",
      "During handling of the above exception, another exception occurred:\n",
      "\n",
      "Traceback (most recent call last):\n",
      "  File \"/Users/ikersanchez/anaconda3/lib/python3.7/site-packages/googleapiclient/discovery_cache/file_cache.py\", line 37, in <module>\n",
      "    from oauth2client.locked_file import LockedFile\n",
      "ModuleNotFoundError: No module named 'oauth2client'\n",
      "\n",
      "During handling of the above exception, another exception occurred:\n",
      "\n",
      "Traceback (most recent call last):\n",
      "  File \"/Users/ikersanchez/anaconda3/lib/python3.7/site-packages/googleapiclient/discovery_cache/__init__.py\", line 41, in autodetect\n",
      "    from . import file_cache\n",
      "  File \"/Users/ikersanchez/anaconda3/lib/python3.7/site-packages/googleapiclient/discovery_cache/file_cache.py\", line 41, in <module>\n",
      "    'file_cache is unavailable when using oauth2client >= 4.0.0 or google-auth')\n",
      "ImportError: file_cache is unavailable when using oauth2client >= 4.0.0 or google-auth\n",
      "I0519 11:19:37.896780 140735859868544 discovery.py:271] URL being requested: GET https://earthengine.googleapis.com/$discovery/rest?version=v1alpha&prettyPrint=false\n",
      "I0519 11:19:38.698542 140735859868544 discovery.py:867] URL being requested: GET https://earthengine.googleapis.com/v1alpha/projects/earthengine-legacy/algorithms?prettyPrint=false&alt=json\n",
      "I0519 11:19:39.296401 140735859868544 discovery.py:867] URL being requested: GET https://earthengine.googleapis.com/v1alpha/projects/earthengine-legacy/assets/projects/soils-revealed/ESA_landcover_ipcc?prettyPrint=false&alt=json\n",
      "I0519 11:19:40.154474 140735859868544 discovery.py:867] URL being requested: POST https://earthengine.googleapis.com/v1alpha/projects/earthengine-legacy/assets?assetId=projects%2Fsoils-revealed%2FESA_landcover_ipcc&prettyPrint=false&alt=json\n",
      "Running command using Cloud API.  Set --no-use_cloud_api to go back to using the API\n",
      "\n",
      "W0519 11:19:43.116539 140735859868544 __init__.py:44] file_cache is unavailable when using oauth2client >= 4.0.0 or google-auth\n",
      "Traceback (most recent call last):\n",
      "  File \"/Users/ikersanchez/anaconda3/lib/python3.7/site-packages/googleapiclient/discovery_cache/__init__.py\", line 36, in autodetect\n",
      "    from google.appengine.api import memcache\n",
      "ModuleNotFoundError: No module named 'google.appengine'\n",
      "\n",
      "During handling of the above exception, another exception occurred:\n",
      "\n",
      "Traceback (most recent call last):\n",
      "  File \"/Users/ikersanchez/anaconda3/lib/python3.7/site-packages/googleapiclient/discovery_cache/file_cache.py\", line 33, in <module>\n",
      "    from oauth2client.contrib.locked_file import LockedFile\n",
      "ModuleNotFoundError: No module named 'oauth2client'\n",
      "\n",
      "During handling of the above exception, another exception occurred:\n",
      "\n",
      "Traceback (most recent call last):\n",
      "  File \"/Users/ikersanchez/anaconda3/lib/python3.7/site-packages/googleapiclient/discovery_cache/file_cache.py\", line 37, in <module>\n",
      "    from oauth2client.locked_file import LockedFile\n",
      "ModuleNotFoundError: No module named 'oauth2client'\n",
      "\n",
      "During handling of the above exception, another exception occurred:\n",
      "\n",
      "Traceback (most recent call last):\n",
      "  File \"/Users/ikersanchez/anaconda3/lib/python3.7/site-packages/googleapiclient/discovery_cache/__init__.py\", line 41, in autodetect\n",
      "    from . import file_cache\n",
      "  File \"/Users/ikersanchez/anaconda3/lib/python3.7/site-packages/googleapiclient/discovery_cache/file_cache.py\", line 41, in <module>\n",
      "    'file_cache is unavailable when using oauth2client >= 4.0.0 or google-auth')\n",
      "ImportError: file_cache is unavailable when using oauth2client >= 4.0.0 or google-auth\n",
      "I0519 11:19:43.117102 140735859868544 discovery.py:271] URL being requested: GET https://earthengine.googleapis.com/$discovery/rest?version=v1alpha&prettyPrint=false\n",
      "W0519 11:19:44.937638 140735859868544 __init__.py:44] file_cache is unavailable when using oauth2client >= 4.0.0 or google-auth\n",
      "Traceback (most recent call last):\n",
      "  File \"/Users/ikersanchez/anaconda3/lib/python3.7/site-packages/googleapiclient/discovery_cache/__init__.py\", line 36, in autodetect\n",
      "    from google.appengine.api import memcache\n",
      "ModuleNotFoundError: No module named 'google.appengine'\n",
      "\n",
      "During handling of the above exception, another exception occurred:\n",
      "\n",
      "Traceback (most recent call last):\n",
      "  File \"/Users/ikersanchez/anaconda3/lib/python3.7/site-packages/googleapiclient/discovery_cache/file_cache.py\", line 33, in <module>\n",
      "    from oauth2client.contrib.locked_file import LockedFile\n",
      "ModuleNotFoundError: No module named 'oauth2client'\n",
      "\n",
      "During handling of the above exception, another exception occurred:\n",
      "\n",
      "Traceback (most recent call last):\n",
      "  File \"/Users/ikersanchez/anaconda3/lib/python3.7/site-packages/googleapiclient/discovery_cache/file_cache.py\", line 37, in <module>\n",
      "    from oauth2client.locked_file import LockedFile\n",
      "ModuleNotFoundError: No module named 'oauth2client'\n",
      "\n",
      "During handling of the above exception, another exception occurred:\n",
      "\n",
      "Traceback (most recent call last):\n",
      "  File \"/Users/ikersanchez/anaconda3/lib/python3.7/site-packages/googleapiclient/discovery_cache/__init__.py\", line 41, in autodetect\n",
      "    from . import file_cache\n",
      "  File \"/Users/ikersanchez/anaconda3/lib/python3.7/site-packages/googleapiclient/discovery_cache/file_cache.py\", line 41, in <module>\n",
      "    'file_cache is unavailable when using oauth2client >= 4.0.0 or google-auth')\n",
      "ImportError: file_cache is unavailable when using oauth2client >= 4.0.0 or google-auth\n",
      "I0519 11:19:44.937979 140735859868544 discovery.py:271] URL being requested: GET https://earthengine.googleapis.com/$discovery/rest?version=v1alpha&prettyPrint=false\n",
      "I0519 11:19:45.731983 140735859868544 discovery.py:867] URL being requested: GET https://earthengine.googleapis.com/v1alpha/projects/earthengine-legacy/algorithms?prettyPrint=false&alt=json\n",
      "I0519 11:19:46.375350 140735859868544 discovery.py:867] URL being requested: POST https://earthengine.googleapis.com/v1alpha/projects/earthengine-legacy/image:import?alt=json\n",
      "Started upload task with ID: QOCDKUVDNZ7E3EZAYETSTLRR\n",
      "Running command using Cloud API.  Set --no-use_cloud_api to go back to using the API\n",
      "\n",
      "W0519 11:19:49.223909 140735859868544 __init__.py:44] file_cache is unavailable when using oauth2client >= 4.0.0 or google-auth\n",
      "Traceback (most recent call last):\n",
      "  File \"/Users/ikersanchez/anaconda3/lib/python3.7/site-packages/googleapiclient/discovery_cache/__init__.py\", line 36, in autodetect\n",
      "    from google.appengine.api import memcache\n",
      "ModuleNotFoundError: No module named 'google.appengine'\n",
      "\n",
      "During handling of the above exception, another exception occurred:\n",
      "\n",
      "Traceback (most recent call last):\n",
      "  File \"/Users/ikersanchez/anaconda3/lib/python3.7/site-packages/googleapiclient/discovery_cache/file_cache.py\", line 33, in <module>\n",
      "    from oauth2client.contrib.locked_file import LockedFile\n",
      "ModuleNotFoundError: No module named 'oauth2client'\n",
      "\n",
      "During handling of the above exception, another exception occurred:\n",
      "\n",
      "Traceback (most recent call last):\n",
      "  File \"/Users/ikersanchez/anaconda3/lib/python3.7/site-packages/googleapiclient/discovery_cache/file_cache.py\", line 37, in <module>\n",
      "    from oauth2client.locked_file import LockedFile\n",
      "ModuleNotFoundError: No module named 'oauth2client'\n",
      "\n",
      "During handling of the above exception, another exception occurred:\n",
      "\n",
      "Traceback (most recent call last):\n",
      "  File \"/Users/ikersanchez/anaconda3/lib/python3.7/site-packages/googleapiclient/discovery_cache/__init__.py\", line 41, in autodetect\n",
      "    from . import file_cache\n",
      "  File \"/Users/ikersanchez/anaconda3/lib/python3.7/site-packages/googleapiclient/discovery_cache/file_cache.py\", line 41, in <module>\n",
      "    'file_cache is unavailable when using oauth2client >= 4.0.0 or google-auth')\n",
      "ImportError: file_cache is unavailable when using oauth2client >= 4.0.0 or google-auth\n",
      "I0519 11:19:49.224460 140735859868544 discovery.py:271] URL being requested: GET https://earthengine.googleapis.com/$discovery/rest?version=v1alpha&prettyPrint=false\n",
      "W0519 11:19:50.304581 140735859868544 __init__.py:44] file_cache is unavailable when using oauth2client >= 4.0.0 or google-auth\n",
      "Traceback (most recent call last):\n",
      "  File \"/Users/ikersanchez/anaconda3/lib/python3.7/site-packages/googleapiclient/discovery_cache/__init__.py\", line 36, in autodetect\n",
      "    from google.appengine.api import memcache\n",
      "ModuleNotFoundError: No module named 'google.appengine'\n",
      "\n",
      "During handling of the above exception, another exception occurred:\n",
      "\n",
      "Traceback (most recent call last):\n",
      "  File \"/Users/ikersanchez/anaconda3/lib/python3.7/site-packages/googleapiclient/discovery_cache/file_cache.py\", line 33, in <module>\n",
      "    from oauth2client.contrib.locked_file import LockedFile\n",
      "ModuleNotFoundError: No module named 'oauth2client'\n",
      "\n",
      "During handling of the above exception, another exception occurred:\n",
      "\n",
      "Traceback (most recent call last):\n",
      "  File \"/Users/ikersanchez/anaconda3/lib/python3.7/site-packages/googleapiclient/discovery_cache/file_cache.py\", line 37, in <module>\n",
      "    from oauth2client.locked_file import LockedFile\n",
      "ModuleNotFoundError: No module named 'oauth2client'\n",
      "\n",
      "During handling of the above exception, another exception occurred:\n",
      "\n",
      "Traceback (most recent call last):\n",
      "  File \"/Users/ikersanchez/anaconda3/lib/python3.7/site-packages/googleapiclient/discovery_cache/__init__.py\", line 41, in autodetect\n",
      "    from . import file_cache\n",
      "  File \"/Users/ikersanchez/anaconda3/lib/python3.7/site-packages/googleapiclient/discovery_cache/file_cache.py\", line 41, in <module>\n",
      "    'file_cache is unavailable when using oauth2client >= 4.0.0 or google-auth')\n",
      "ImportError: file_cache is unavailable when using oauth2client >= 4.0.0 or google-auth\n",
      "I0519 11:19:50.305001 140735859868544 discovery.py:271] URL being requested: GET https://earthengine.googleapis.com/$discovery/rest?version=v1alpha&prettyPrint=false\n",
      "I0519 11:19:51.094351 140735859868544 discovery.py:867] URL being requested: GET https://earthengine.googleapis.com/v1alpha/projects/earthengine-legacy/algorithms?prettyPrint=false&alt=json\n",
      "I0519 11:19:51.740837 140735859868544 discovery.py:867] URL being requested: POST https://earthengine.googleapis.com/v1alpha/projects/earthengine-legacy/image:import?alt=json\n",
      "Started upload task with ID: 6TX2DZRPNXEBVOP4ED2SWGQL\n",
      "Running command using Cloud API.  Set --no-use_cloud_api to go back to using the API\n",
      "\n",
      "W0519 11:19:55.092998 140735859868544 __init__.py:44] file_cache is unavailable when using oauth2client >= 4.0.0 or google-auth\n",
      "Traceback (most recent call last):\n",
      "  File \"/Users/ikersanchez/anaconda3/lib/python3.7/site-packages/googleapiclient/discovery_cache/__init__.py\", line 36, in autodetect\n",
      "    from google.appengine.api import memcache\n",
      "ModuleNotFoundError: No module named 'google.appengine'\n",
      "\n",
      "During handling of the above exception, another exception occurred:\n",
      "\n",
      "Traceback (most recent call last):\n",
      "  File \"/Users/ikersanchez/anaconda3/lib/python3.7/site-packages/googleapiclient/discovery_cache/file_cache.py\", line 33, in <module>\n",
      "    from oauth2client.contrib.locked_file import LockedFile\n",
      "ModuleNotFoundError: No module named 'oauth2client'\n",
      "\n",
      "During handling of the above exception, another exception occurred:\n",
      "\n",
      "Traceback (most recent call last):\n",
      "  File \"/Users/ikersanchez/anaconda3/lib/python3.7/site-packages/googleapiclient/discovery_cache/file_cache.py\", line 37, in <module>\n",
      "    from oauth2client.locked_file import LockedFile\n",
      "ModuleNotFoundError: No module named 'oauth2client'\n",
      "\n",
      "During handling of the above exception, another exception occurred:\n",
      "\n",
      "Traceback (most recent call last):\n",
      "  File \"/Users/ikersanchez/anaconda3/lib/python3.7/site-packages/googleapiclient/discovery_cache/__init__.py\", line 41, in autodetect\n",
      "    from . import file_cache\n",
      "  File \"/Users/ikersanchez/anaconda3/lib/python3.7/site-packages/googleapiclient/discovery_cache/file_cache.py\", line 41, in <module>\n",
      "    'file_cache is unavailable when using oauth2client >= 4.0.0 or google-auth')\n",
      "ImportError: file_cache is unavailable when using oauth2client >= 4.0.0 or google-auth\n",
      "I0519 11:19:55.093538 140735859868544 discovery.py:271] URL being requested: GET https://earthengine.googleapis.com/$discovery/rest?version=v1alpha&prettyPrint=false\n",
      "W0519 11:19:56.017878 140735859868544 __init__.py:44] file_cache is unavailable when using oauth2client >= 4.0.0 or google-auth\n",
      "Traceback (most recent call last):\n",
      "  File \"/Users/ikersanchez/anaconda3/lib/python3.7/site-packages/googleapiclient/discovery_cache/__init__.py\", line 36, in autodetect\n",
      "    from google.appengine.api import memcache\n",
      "ModuleNotFoundError: No module named 'google.appengine'\n",
      "\n",
      "During handling of the above exception, another exception occurred:\n",
      "\n",
      "Traceback (most recent call last):\n",
      "  File \"/Users/ikersanchez/anaconda3/lib/python3.7/site-packages/googleapiclient/discovery_cache/file_cache.py\", line 33, in <module>\n",
      "    from oauth2client.contrib.locked_file import LockedFile\n",
      "ModuleNotFoundError: No module named 'oauth2client'\n",
      "\n",
      "During handling of the above exception, another exception occurred:\n",
      "\n",
      "Traceback (most recent call last):\n",
      "  File \"/Users/ikersanchez/anaconda3/lib/python3.7/site-packages/googleapiclient/discovery_cache/file_cache.py\", line 37, in <module>\n",
      "    from oauth2client.locked_file import LockedFile\n",
      "ModuleNotFoundError: No module named 'oauth2client'\n",
      "\n",
      "During handling of the above exception, another exception occurred:\n",
      "\n",
      "Traceback (most recent call last):\n",
      "  File \"/Users/ikersanchez/anaconda3/lib/python3.7/site-packages/googleapiclient/discovery_cache/__init__.py\", line 41, in autodetect\n",
      "    from . import file_cache\n",
      "  File \"/Users/ikersanchez/anaconda3/lib/python3.7/site-packages/googleapiclient/discovery_cache/file_cache.py\", line 41, in <module>\n",
      "    'file_cache is unavailable when using oauth2client >= 4.0.0 or google-auth')\n",
      "ImportError: file_cache is unavailable when using oauth2client >= 4.0.0 or google-auth\n",
      "I0519 11:19:56.018288 140735859868544 discovery.py:271] URL being requested: GET https://earthengine.googleapis.com/$discovery/rest?version=v1alpha&prettyPrint=false\n",
      "I0519 11:19:57.726599 140735859868544 discovery.py:867] URL being requested: GET https://earthengine.googleapis.com/v1alpha/projects/earthengine-legacy/algorithms?prettyPrint=false&alt=json\n",
      "I0519 11:19:58.327612 140735859868544 discovery.py:867] URL being requested: POST https://earthengine.googleapis.com/v1alpha/projects/earthengine-legacy/image:import?alt=json\n",
      "Started upload task with ID: R5WUHX5POQRFXDEMZQHN4IKP\n",
      "Running command using Cloud API.  Set --no-use_cloud_api to go back to using the API\n",
      "\n",
      "W0519 11:20:01.649933 140735859868544 __init__.py:44] file_cache is unavailable when using oauth2client >= 4.0.0 or google-auth\n",
      "Traceback (most recent call last):\n",
      "  File \"/Users/ikersanchez/anaconda3/lib/python3.7/site-packages/googleapiclient/discovery_cache/__init__.py\", line 36, in autodetect\n",
      "    from google.appengine.api import memcache\n",
      "ModuleNotFoundError: No module named 'google.appengine'\n",
      "\n",
      "During handling of the above exception, another exception occurred:\n",
      "\n",
      "Traceback (most recent call last):\n",
      "  File \"/Users/ikersanchez/anaconda3/lib/python3.7/site-packages/googleapiclient/discovery_cache/file_cache.py\", line 33, in <module>\n",
      "    from oauth2client.contrib.locked_file import LockedFile\n",
      "ModuleNotFoundError: No module named 'oauth2client'\n",
      "\n",
      "During handling of the above exception, another exception occurred:\n",
      "\n",
      "Traceback (most recent call last):\n",
      "  File \"/Users/ikersanchez/anaconda3/lib/python3.7/site-packages/googleapiclient/discovery_cache/file_cache.py\", line 37, in <module>\n",
      "    from oauth2client.locked_file import LockedFile\n",
      "ModuleNotFoundError: No module named 'oauth2client'\n",
      "\n",
      "During handling of the above exception, another exception occurred:\n",
      "\n",
      "Traceback (most recent call last):\n",
      "  File \"/Users/ikersanchez/anaconda3/lib/python3.7/site-packages/googleapiclient/discovery_cache/__init__.py\", line 41, in autodetect\n",
      "    from . import file_cache\n",
      "  File \"/Users/ikersanchez/anaconda3/lib/python3.7/site-packages/googleapiclient/discovery_cache/file_cache.py\", line 41, in <module>\n",
      "    'file_cache is unavailable when using oauth2client >= 4.0.0 or google-auth')\n",
      "ImportError: file_cache is unavailable when using oauth2client >= 4.0.0 or google-auth\n",
      "I0519 11:20:01.650450 140735859868544 discovery.py:271] URL being requested: GET https://earthengine.googleapis.com/$discovery/rest?version=v1alpha&prettyPrint=false\n",
      "W0519 11:20:02.583259 140735859868544 __init__.py:44] file_cache is unavailable when using oauth2client >= 4.0.0 or google-auth\n",
      "Traceback (most recent call last):\n",
      "  File \"/Users/ikersanchez/anaconda3/lib/python3.7/site-packages/googleapiclient/discovery_cache/__init__.py\", line 36, in autodetect\n",
      "    from google.appengine.api import memcache\n",
      "ModuleNotFoundError: No module named 'google.appengine'\n",
      "\n",
      "During handling of the above exception, another exception occurred:\n",
      "\n",
      "Traceback (most recent call last):\n",
      "  File \"/Users/ikersanchez/anaconda3/lib/python3.7/site-packages/googleapiclient/discovery_cache/file_cache.py\", line 33, in <module>\n",
      "    from oauth2client.contrib.locked_file import LockedFile\n",
      "ModuleNotFoundError: No module named 'oauth2client'\n",
      "\n",
      "During handling of the above exception, another exception occurred:\n",
      "\n",
      "Traceback (most recent call last):\n",
      "  File \"/Users/ikersanchez/anaconda3/lib/python3.7/site-packages/googleapiclient/discovery_cache/file_cache.py\", line 37, in <module>\n",
      "    from oauth2client.locked_file import LockedFile\n",
      "ModuleNotFoundError: No module named 'oauth2client'\n",
      "\n",
      "During handling of the above exception, another exception occurred:\n",
      "\n",
      "Traceback (most recent call last):\n",
      "  File \"/Users/ikersanchez/anaconda3/lib/python3.7/site-packages/googleapiclient/discovery_cache/__init__.py\", line 41, in autodetect\n",
      "    from . import file_cache\n",
      "  File \"/Users/ikersanchez/anaconda3/lib/python3.7/site-packages/googleapiclient/discovery_cache/file_cache.py\", line 41, in <module>\n",
      "    'file_cache is unavailable when using oauth2client >= 4.0.0 or google-auth')\n",
      "ImportError: file_cache is unavailable when using oauth2client >= 4.0.0 or google-auth\n",
      "I0519 11:20:02.583698 140735859868544 discovery.py:271] URL being requested: GET https://earthengine.googleapis.com/$discovery/rest?version=v1alpha&prettyPrint=false\n",
      "I0519 11:20:03.414647 140735859868544 discovery.py:867] URL being requested: GET https://earthengine.googleapis.com/v1alpha/projects/earthengine-legacy/algorithms?prettyPrint=false&alt=json\n",
      "I0519 11:20:04.038832 140735859868544 discovery.py:867] URL being requested: POST https://earthengine.googleapis.com/v1alpha/projects/earthengine-legacy/image:import?alt=json\n",
      "Started upload task with ID: YD5W73JZJNPSLPRIEYF7H7SY\n",
      "Running command using Cloud API.  Set --no-use_cloud_api to go back to using the API\n",
      "\n",
      "W0519 11:20:07.559749 140735859868544 __init__.py:44] file_cache is unavailable when using oauth2client >= 4.0.0 or google-auth\n",
      "Traceback (most recent call last):\n",
      "  File \"/Users/ikersanchez/anaconda3/lib/python3.7/site-packages/googleapiclient/discovery_cache/__init__.py\", line 36, in autodetect\n",
      "    from google.appengine.api import memcache\n",
      "ModuleNotFoundError: No module named 'google.appengine'\n",
      "\n",
      "During handling of the above exception, another exception occurred:\n",
      "\n",
      "Traceback (most recent call last):\n",
      "  File \"/Users/ikersanchez/anaconda3/lib/python3.7/site-packages/googleapiclient/discovery_cache/file_cache.py\", line 33, in <module>\n",
      "    from oauth2client.contrib.locked_file import LockedFile\n",
      "ModuleNotFoundError: No module named 'oauth2client'\n",
      "\n",
      "During handling of the above exception, another exception occurred:\n",
      "\n",
      "Traceback (most recent call last):\n",
      "  File \"/Users/ikersanchez/anaconda3/lib/python3.7/site-packages/googleapiclient/discovery_cache/file_cache.py\", line 37, in <module>\n",
      "    from oauth2client.locked_file import LockedFile\n",
      "ModuleNotFoundError: No module named 'oauth2client'\n",
      "\n",
      "During handling of the above exception, another exception occurred:\n",
      "\n",
      "Traceback (most recent call last):\n",
      "  File \"/Users/ikersanchez/anaconda3/lib/python3.7/site-packages/googleapiclient/discovery_cache/__init__.py\", line 41, in autodetect\n",
      "    from . import file_cache\n",
      "  File \"/Users/ikersanchez/anaconda3/lib/python3.7/site-packages/googleapiclient/discovery_cache/file_cache.py\", line 41, in <module>\n",
      "    'file_cache is unavailable when using oauth2client >= 4.0.0 or google-auth')\n",
      "ImportError: file_cache is unavailable when using oauth2client >= 4.0.0 or google-auth\n",
      "I0519 11:20:07.560451 140735859868544 discovery.py:271] URL being requested: GET https://earthengine.googleapis.com/$discovery/rest?version=v1alpha&prettyPrint=false\n",
      "W0519 11:20:08.526518 140735859868544 __init__.py:44] file_cache is unavailable when using oauth2client >= 4.0.0 or google-auth\n",
      "Traceback (most recent call last):\n",
      "  File \"/Users/ikersanchez/anaconda3/lib/python3.7/site-packages/googleapiclient/discovery_cache/__init__.py\", line 36, in autodetect\n",
      "    from google.appengine.api import memcache\n",
      "ModuleNotFoundError: No module named 'google.appengine'\n",
      "\n",
      "During handling of the above exception, another exception occurred:\n",
      "\n",
      "Traceback (most recent call last):\n",
      "  File \"/Users/ikersanchez/anaconda3/lib/python3.7/site-packages/googleapiclient/discovery_cache/file_cache.py\", line 33, in <module>\n",
      "    from oauth2client.contrib.locked_file import LockedFile\n",
      "ModuleNotFoundError: No module named 'oauth2client'\n",
      "\n",
      "During handling of the above exception, another exception occurred:\n",
      "\n",
      "Traceback (most recent call last):\n",
      "  File \"/Users/ikersanchez/anaconda3/lib/python3.7/site-packages/googleapiclient/discovery_cache/file_cache.py\", line 37, in <module>\n",
      "    from oauth2client.locked_file import LockedFile\n",
      "ModuleNotFoundError: No module named 'oauth2client'\n",
      "\n",
      "During handling of the above exception, another exception occurred:\n",
      "\n",
      "Traceback (most recent call last):\n",
      "  File \"/Users/ikersanchez/anaconda3/lib/python3.7/site-packages/googleapiclient/discovery_cache/__init__.py\", line 41, in autodetect\n",
      "    from . import file_cache\n",
      "  File \"/Users/ikersanchez/anaconda3/lib/python3.7/site-packages/googleapiclient/discovery_cache/file_cache.py\", line 41, in <module>\n",
      "    'file_cache is unavailable when using oauth2client >= 4.0.0 or google-auth')\n",
      "ImportError: file_cache is unavailable when using oauth2client >= 4.0.0 or google-auth\n",
      "I0519 11:20:08.526875 140735859868544 discovery.py:271] URL being requested: GET https://earthengine.googleapis.com/$discovery/rest?version=v1alpha&prettyPrint=false\n",
      "I0519 11:20:09.423610 140735859868544 discovery.py:867] URL being requested: GET https://earthengine.googleapis.com/v1alpha/projects/earthengine-legacy/algorithms?prettyPrint=false&alt=json\n",
      "I0519 11:20:10.680798 140735859868544 discovery.py:867] URL being requested: POST https://earthengine.googleapis.com/v1alpha/projects/earthengine-legacy/image:import?alt=json\n",
      "Started upload task with ID: 64AE5GYITDVPEPSMQFHNI6TZ\n",
      "Running command using Cloud API.  Set --no-use_cloud_api to go back to using the API\n",
      "\n",
      "W0519 11:20:14.297317 140735859868544 __init__.py:44] file_cache is unavailable when using oauth2client >= 4.0.0 or google-auth\n",
      "Traceback (most recent call last):\n",
      "  File \"/Users/ikersanchez/anaconda3/lib/python3.7/site-packages/googleapiclient/discovery_cache/__init__.py\", line 36, in autodetect\n",
      "    from google.appengine.api import memcache\n",
      "ModuleNotFoundError: No module named 'google.appengine'\n",
      "\n",
      "During handling of the above exception, another exception occurred:\n",
      "\n",
      "Traceback (most recent call last):\n",
      "  File \"/Users/ikersanchez/anaconda3/lib/python3.7/site-packages/googleapiclient/discovery_cache/file_cache.py\", line 33, in <module>\n",
      "    from oauth2client.contrib.locked_file import LockedFile\n",
      "ModuleNotFoundError: No module named 'oauth2client'\n",
      "\n",
      "During handling of the above exception, another exception occurred:\n",
      "\n",
      "Traceback (most recent call last):\n",
      "  File \"/Users/ikersanchez/anaconda3/lib/python3.7/site-packages/googleapiclient/discovery_cache/file_cache.py\", line 37, in <module>\n",
      "    from oauth2client.locked_file import LockedFile\n",
      "ModuleNotFoundError: No module named 'oauth2client'\n",
      "\n",
      "During handling of the above exception, another exception occurred:\n",
      "\n",
      "Traceback (most recent call last):\n",
      "  File \"/Users/ikersanchez/anaconda3/lib/python3.7/site-packages/googleapiclient/discovery_cache/__init__.py\", line 41, in autodetect\n",
      "    from . import file_cache\n",
      "  File \"/Users/ikersanchez/anaconda3/lib/python3.7/site-packages/googleapiclient/discovery_cache/file_cache.py\", line 41, in <module>\n",
      "    'file_cache is unavailable when using oauth2client >= 4.0.0 or google-auth')\n",
      "ImportError: file_cache is unavailable when using oauth2client >= 4.0.0 or google-auth\n",
      "I0519 11:20:14.297857 140735859868544 discovery.py:271] URL being requested: GET https://earthengine.googleapis.com/$discovery/rest?version=v1alpha&prettyPrint=false\n",
      "W0519 11:20:15.341722 140735859868544 __init__.py:44] file_cache is unavailable when using oauth2client >= 4.0.0 or google-auth\n",
      "Traceback (most recent call last):\n",
      "  File \"/Users/ikersanchez/anaconda3/lib/python3.7/site-packages/googleapiclient/discovery_cache/__init__.py\", line 36, in autodetect\n",
      "    from google.appengine.api import memcache\n",
      "ModuleNotFoundError: No module named 'google.appengine'\n",
      "\n",
      "During handling of the above exception, another exception occurred:\n",
      "\n",
      "Traceback (most recent call last):\n",
      "  File \"/Users/ikersanchez/anaconda3/lib/python3.7/site-packages/googleapiclient/discovery_cache/file_cache.py\", line 33, in <module>\n",
      "    from oauth2client.contrib.locked_file import LockedFile\n",
      "ModuleNotFoundError: No module named 'oauth2client'\n",
      "\n",
      "During handling of the above exception, another exception occurred:\n",
      "\n",
      "Traceback (most recent call last):\n",
      "  File \"/Users/ikersanchez/anaconda3/lib/python3.7/site-packages/googleapiclient/discovery_cache/file_cache.py\", line 37, in <module>\n",
      "    from oauth2client.locked_file import LockedFile\n",
      "ModuleNotFoundError: No module named 'oauth2client'\n",
      "\n",
      "During handling of the above exception, another exception occurred:\n",
      "\n",
      "Traceback (most recent call last):\n",
      "  File \"/Users/ikersanchez/anaconda3/lib/python3.7/site-packages/googleapiclient/discovery_cache/__init__.py\", line 41, in autodetect\n",
      "    from . import file_cache\n",
      "  File \"/Users/ikersanchez/anaconda3/lib/python3.7/site-packages/googleapiclient/discovery_cache/file_cache.py\", line 41, in <module>\n",
      "    'file_cache is unavailable when using oauth2client >= 4.0.0 or google-auth')\n",
      "ImportError: file_cache is unavailable when using oauth2client >= 4.0.0 or google-auth\n",
      "I0519 11:20:15.342113 140735859868544 discovery.py:271] URL being requested: GET https://earthengine.googleapis.com/$discovery/rest?version=v1alpha&prettyPrint=false\n",
      "I0519 11:20:16.359730 140735859868544 discovery.py:867] URL being requested: GET https://earthengine.googleapis.com/v1alpha/projects/earthengine-legacy/algorithms?prettyPrint=false&alt=json\n",
      "I0519 11:20:17.668792 140735859868544 discovery.py:867] URL being requested: POST https://earthengine.googleapis.com/v1alpha/projects/earthengine-legacy/image:import?alt=json\n",
      "Started upload task with ID: ELM7GEU2VKABMEQI4BI6G6OR\n",
      "Running command using Cloud API.  Set --no-use_cloud_api to go back to using the API\n",
      "\n",
      "W0519 11:22:28.295228 140735859868544 __init__.py:44] file_cache is unavailable when using oauth2client >= 4.0.0 or google-auth\n",
      "Traceback (most recent call last):\n",
      "  File \"/Users/ikersanchez/anaconda3/lib/python3.7/site-packages/googleapiclient/discovery_cache/__init__.py\", line 36, in autodetect\n",
      "    from google.appengine.api import memcache\n",
      "ModuleNotFoundError: No module named 'google.appengine'\n",
      "\n",
      "During handling of the above exception, another exception occurred:\n",
      "\n",
      "Traceback (most recent call last):\n",
      "  File \"/Users/ikersanchez/anaconda3/lib/python3.7/site-packages/googleapiclient/discovery_cache/file_cache.py\", line 33, in <module>\n",
      "    from oauth2client.contrib.locked_file import LockedFile\n",
      "ModuleNotFoundError: No module named 'oauth2client'\n",
      "\n",
      "During handling of the above exception, another exception occurred:\n",
      "\n",
      "Traceback (most recent call last):\n",
      "  File \"/Users/ikersanchez/anaconda3/lib/python3.7/site-packages/googleapiclient/discovery_cache/file_cache.py\", line 37, in <module>\n",
      "    from oauth2client.locked_file import LockedFile\n",
      "ModuleNotFoundError: No module named 'oauth2client'\n",
      "\n",
      "During handling of the above exception, another exception occurred:\n",
      "\n",
      "Traceback (most recent call last):\n",
      "  File \"/Users/ikersanchez/anaconda3/lib/python3.7/site-packages/googleapiclient/discovery_cache/__init__.py\", line 41, in autodetect\n",
      "    from . import file_cache\n",
      "  File \"/Users/ikersanchez/anaconda3/lib/python3.7/site-packages/googleapiclient/discovery_cache/file_cache.py\", line 41, in <module>\n",
      "    'file_cache is unavailable when using oauth2client >= 4.0.0 or google-auth')\n",
      "ImportError: file_cache is unavailable when using oauth2client >= 4.0.0 or google-auth\n",
      "I0519 11:22:28.296832 140735859868544 discovery.py:271] URL being requested: GET https://earthengine.googleapis.com/$discovery/rest?version=v1alpha&prettyPrint=false\n",
      "W0519 11:22:29.226665 140735859868544 __init__.py:44] file_cache is unavailable when using oauth2client >= 4.0.0 or google-auth\n",
      "Traceback (most recent call last):\n",
      "  File \"/Users/ikersanchez/anaconda3/lib/python3.7/site-packages/googleapiclient/discovery_cache/__init__.py\", line 36, in autodetect\n",
      "    from google.appengine.api import memcache\n",
      "ModuleNotFoundError: No module named 'google.appengine'\n",
      "\n",
      "During handling of the above exception, another exception occurred:\n",
      "\n",
      "Traceback (most recent call last):\n",
      "  File \"/Users/ikersanchez/anaconda3/lib/python3.7/site-packages/googleapiclient/discovery_cache/file_cache.py\", line 33, in <module>\n",
      "    from oauth2client.contrib.locked_file import LockedFile\n",
      "ModuleNotFoundError: No module named 'oauth2client'\n",
      "\n",
      "During handling of the above exception, another exception occurred:\n",
      "\n",
      "Traceback (most recent call last):\n",
      "  File \"/Users/ikersanchez/anaconda3/lib/python3.7/site-packages/googleapiclient/discovery_cache/file_cache.py\", line 37, in <module>\n",
      "    from oauth2client.locked_file import LockedFile\n",
      "ModuleNotFoundError: No module named 'oauth2client'\n",
      "\n",
      "During handling of the above exception, another exception occurred:\n",
      "\n",
      "Traceback (most recent call last):\n",
      "  File \"/Users/ikersanchez/anaconda3/lib/python3.7/site-packages/googleapiclient/discovery_cache/__init__.py\", line 41, in autodetect\n",
      "    from . import file_cache\n",
      "  File \"/Users/ikersanchez/anaconda3/lib/python3.7/site-packages/googleapiclient/discovery_cache/file_cache.py\", line 41, in <module>\n",
      "    'file_cache is unavailable when using oauth2client >= 4.0.0 or google-auth')\n",
      "ImportError: file_cache is unavailable when using oauth2client >= 4.0.0 or google-auth\n",
      "I0519 11:22:29.227033 140735859868544 discovery.py:271] URL being requested: GET https://earthengine.googleapis.com/$discovery/rest?version=v1alpha&prettyPrint=false\n",
      "I0519 11:22:30.320428 140735859868544 discovery.py:867] URL being requested: GET https://earthengine.googleapis.com/v1alpha/projects/earthengine-legacy/algorithms?prettyPrint=false&alt=json\n",
      "I0519 11:22:31.544719 140735859868544 discovery.py:867] URL being requested: POST https://earthengine.googleapis.com/v1alpha/projects/earthengine-legacy/image:import?alt=json\n",
      "Started upload task with ID: JVXEU3PCNCKHWOHYEPMGO622\n",
      "Running command using Cloud API.  Set --no-use_cloud_api to go back to using the API\n",
      "\n",
      "W0519 11:22:34.423941 140735859868544 __init__.py:44] file_cache is unavailable when using oauth2client >= 4.0.0 or google-auth\n",
      "Traceback (most recent call last):\n",
      "  File \"/Users/ikersanchez/anaconda3/lib/python3.7/site-packages/googleapiclient/discovery_cache/__init__.py\", line 36, in autodetect\n",
      "    from google.appengine.api import memcache\n",
      "ModuleNotFoundError: No module named 'google.appengine'\n",
      "\n",
      "During handling of the above exception, another exception occurred:\n",
      "\n",
      "Traceback (most recent call last):\n",
      "  File \"/Users/ikersanchez/anaconda3/lib/python3.7/site-packages/googleapiclient/discovery_cache/file_cache.py\", line 33, in <module>\n",
      "    from oauth2client.contrib.locked_file import LockedFile\n",
      "ModuleNotFoundError: No module named 'oauth2client'\n",
      "\n",
      "During handling of the above exception, another exception occurred:\n",
      "\n",
      "Traceback (most recent call last):\n",
      "  File \"/Users/ikersanchez/anaconda3/lib/python3.7/site-packages/googleapiclient/discovery_cache/file_cache.py\", line 37, in <module>\n",
      "    from oauth2client.locked_file import LockedFile\n",
      "ModuleNotFoundError: No module named 'oauth2client'\n",
      "\n",
      "During handling of the above exception, another exception occurred:\n",
      "\n",
      "Traceback (most recent call last):\n",
      "  File \"/Users/ikersanchez/anaconda3/lib/python3.7/site-packages/googleapiclient/discovery_cache/__init__.py\", line 41, in autodetect\n",
      "    from . import file_cache\n",
      "  File \"/Users/ikersanchez/anaconda3/lib/python3.7/site-packages/googleapiclient/discovery_cache/file_cache.py\", line 41, in <module>\n",
      "    'file_cache is unavailable when using oauth2client >= 4.0.0 or google-auth')\n",
      "ImportError: file_cache is unavailable when using oauth2client >= 4.0.0 or google-auth\n",
      "I0519 11:22:34.424483 140735859868544 discovery.py:271] URL being requested: GET https://earthengine.googleapis.com/$discovery/rest?version=v1alpha&prettyPrint=false\n",
      "W0519 11:22:35.382156 140735859868544 __init__.py:44] file_cache is unavailable when using oauth2client >= 4.0.0 or google-auth\n",
      "Traceback (most recent call last):\n",
      "  File \"/Users/ikersanchez/anaconda3/lib/python3.7/site-packages/googleapiclient/discovery_cache/__init__.py\", line 36, in autodetect\n",
      "    from google.appengine.api import memcache\n",
      "ModuleNotFoundError: No module named 'google.appengine'\n",
      "\n",
      "During handling of the above exception, another exception occurred:\n",
      "\n",
      "Traceback (most recent call last):\n",
      "  File \"/Users/ikersanchez/anaconda3/lib/python3.7/site-packages/googleapiclient/discovery_cache/file_cache.py\", line 33, in <module>\n",
      "    from oauth2client.contrib.locked_file import LockedFile\n",
      "ModuleNotFoundError: No module named 'oauth2client'\n",
      "\n",
      "During handling of the above exception, another exception occurred:\n",
      "\n",
      "Traceback (most recent call last):\n",
      "  File \"/Users/ikersanchez/anaconda3/lib/python3.7/site-packages/googleapiclient/discovery_cache/file_cache.py\", line 37, in <module>\n",
      "    from oauth2client.locked_file import LockedFile\n",
      "ModuleNotFoundError: No module named 'oauth2client'\n",
      "\n",
      "During handling of the above exception, another exception occurred:\n",
      "\n",
      "Traceback (most recent call last):\n",
      "  File \"/Users/ikersanchez/anaconda3/lib/python3.7/site-packages/googleapiclient/discovery_cache/__init__.py\", line 41, in autodetect\n",
      "    from . import file_cache\n",
      "  File \"/Users/ikersanchez/anaconda3/lib/python3.7/site-packages/googleapiclient/discovery_cache/file_cache.py\", line 41, in <module>\n",
      "    'file_cache is unavailable when using oauth2client >= 4.0.0 or google-auth')\n",
      "ImportError: file_cache is unavailable when using oauth2client >= 4.0.0 or google-auth\n",
      "I0519 11:22:35.382577 140735859868544 discovery.py:271] URL being requested: GET https://earthengine.googleapis.com/$discovery/rest?version=v1alpha&prettyPrint=false\n",
      "I0519 11:22:36.170050 140735859868544 discovery.py:867] URL being requested: GET https://earthengine.googleapis.com/v1alpha/projects/earthengine-legacy/algorithms?prettyPrint=false&alt=json\n",
      "I0519 11:22:36.838884 140735859868544 discovery.py:867] URL being requested: POST https://earthengine.googleapis.com/v1alpha/projects/earthengine-legacy/image:import?alt=json\n",
      "Started upload task with ID: IJ6I6A2HUB77Z63YTFVMW4HL\n",
      "Running command using Cloud API.  Set --no-use_cloud_api to go back to using the API\n",
      "\n",
      "W0519 11:22:39.969815 140735859868544 __init__.py:44] file_cache is unavailable when using oauth2client >= 4.0.0 or google-auth\n",
      "Traceback (most recent call last):\n",
      "  File \"/Users/ikersanchez/anaconda3/lib/python3.7/site-packages/googleapiclient/discovery_cache/__init__.py\", line 36, in autodetect\n",
      "    from google.appengine.api import memcache\n",
      "ModuleNotFoundError: No module named 'google.appengine'\n",
      "\n",
      "During handling of the above exception, another exception occurred:\n",
      "\n",
      "Traceback (most recent call last):\n",
      "  File \"/Users/ikersanchez/anaconda3/lib/python3.7/site-packages/googleapiclient/discovery_cache/file_cache.py\", line 33, in <module>\n",
      "    from oauth2client.contrib.locked_file import LockedFile\n",
      "ModuleNotFoundError: No module named 'oauth2client'\n",
      "\n",
      "During handling of the above exception, another exception occurred:\n",
      "\n",
      "Traceback (most recent call last):\n",
      "  File \"/Users/ikersanchez/anaconda3/lib/python3.7/site-packages/googleapiclient/discovery_cache/file_cache.py\", line 37, in <module>\n",
      "    from oauth2client.locked_file import LockedFile\n",
      "ModuleNotFoundError: No module named 'oauth2client'\n",
      "\n",
      "During handling of the above exception, another exception occurred:\n",
      "\n",
      "Traceback (most recent call last):\n",
      "  File \"/Users/ikersanchez/anaconda3/lib/python3.7/site-packages/googleapiclient/discovery_cache/__init__.py\", line 41, in autodetect\n",
      "    from . import file_cache\n",
      "  File \"/Users/ikersanchez/anaconda3/lib/python3.7/site-packages/googleapiclient/discovery_cache/file_cache.py\", line 41, in <module>\n",
      "    'file_cache is unavailable when using oauth2client >= 4.0.0 or google-auth')\n",
      "ImportError: file_cache is unavailable when using oauth2client >= 4.0.0 or google-auth\n",
      "I0519 11:22:39.970371 140735859868544 discovery.py:271] URL being requested: GET https://earthengine.googleapis.com/$discovery/rest?version=v1alpha&prettyPrint=false\n",
      "W0519 11:22:40.889424 140735859868544 __init__.py:44] file_cache is unavailable when using oauth2client >= 4.0.0 or google-auth\n",
      "Traceback (most recent call last):\n",
      "  File \"/Users/ikersanchez/anaconda3/lib/python3.7/site-packages/googleapiclient/discovery_cache/__init__.py\", line 36, in autodetect\n",
      "    from google.appengine.api import memcache\n",
      "ModuleNotFoundError: No module named 'google.appengine'\n",
      "\n",
      "During handling of the above exception, another exception occurred:\n",
      "\n",
      "Traceback (most recent call last):\n",
      "  File \"/Users/ikersanchez/anaconda3/lib/python3.7/site-packages/googleapiclient/discovery_cache/file_cache.py\", line 33, in <module>\n",
      "    from oauth2client.contrib.locked_file import LockedFile\n",
      "ModuleNotFoundError: No module named 'oauth2client'\n",
      "\n",
      "During handling of the above exception, another exception occurred:\n",
      "\n",
      "Traceback (most recent call last):\n",
      "  File \"/Users/ikersanchez/anaconda3/lib/python3.7/site-packages/googleapiclient/discovery_cache/file_cache.py\", line 37, in <module>\n",
      "    from oauth2client.locked_file import LockedFile\n",
      "ModuleNotFoundError: No module named 'oauth2client'\n",
      "\n",
      "During handling of the above exception, another exception occurred:\n",
      "\n",
      "Traceback (most recent call last):\n",
      "  File \"/Users/ikersanchez/anaconda3/lib/python3.7/site-packages/googleapiclient/discovery_cache/__init__.py\", line 41, in autodetect\n",
      "    from . import file_cache\n",
      "  File \"/Users/ikersanchez/anaconda3/lib/python3.7/site-packages/googleapiclient/discovery_cache/file_cache.py\", line 41, in <module>\n",
      "    'file_cache is unavailable when using oauth2client >= 4.0.0 or google-auth')\n",
      "ImportError: file_cache is unavailable when using oauth2client >= 4.0.0 or google-auth\n",
      "I0519 11:22:40.889781 140735859868544 discovery.py:271] URL being requested: GET https://earthengine.googleapis.com/$discovery/rest?version=v1alpha&prettyPrint=false\n",
      "I0519 11:22:41.789562 140735859868544 discovery.py:867] URL being requested: GET https://earthengine.googleapis.com/v1alpha/projects/earthengine-legacy/algorithms?prettyPrint=false&alt=json\n",
      "I0519 11:22:42.375595 140735859868544 discovery.py:867] URL being requested: POST https://earthengine.googleapis.com/v1alpha/projects/earthengine-legacy/image:import?alt=json\n",
      "Started upload task with ID: XLV5TRUO2DTTHVCHWVQNACLJ\n",
      "Running command using Cloud API.  Set --no-use_cloud_api to go back to using the API\n",
      "\n",
      "W0519 11:22:45.660593 140735859868544 __init__.py:44] file_cache is unavailable when using oauth2client >= 4.0.0 or google-auth\n",
      "Traceback (most recent call last):\n",
      "  File \"/Users/ikersanchez/anaconda3/lib/python3.7/site-packages/googleapiclient/discovery_cache/__init__.py\", line 36, in autodetect\n",
      "    from google.appengine.api import memcache\n",
      "ModuleNotFoundError: No module named 'google.appengine'\n",
      "\n",
      "During handling of the above exception, another exception occurred:\n",
      "\n",
      "Traceback (most recent call last):\n",
      "  File \"/Users/ikersanchez/anaconda3/lib/python3.7/site-packages/googleapiclient/discovery_cache/file_cache.py\", line 33, in <module>\n",
      "    from oauth2client.contrib.locked_file import LockedFile\n",
      "ModuleNotFoundError: No module named 'oauth2client'\n",
      "\n",
      "During handling of the above exception, another exception occurred:\n",
      "\n",
      "Traceback (most recent call last):\n",
      "  File \"/Users/ikersanchez/anaconda3/lib/python3.7/site-packages/googleapiclient/discovery_cache/file_cache.py\", line 37, in <module>\n",
      "    from oauth2client.locked_file import LockedFile\n",
      "ModuleNotFoundError: No module named 'oauth2client'\n",
      "\n",
      "During handling of the above exception, another exception occurred:\n",
      "\n",
      "Traceback (most recent call last):\n",
      "  File \"/Users/ikersanchez/anaconda3/lib/python3.7/site-packages/googleapiclient/discovery_cache/__init__.py\", line 41, in autodetect\n",
      "    from . import file_cache\n",
      "  File \"/Users/ikersanchez/anaconda3/lib/python3.7/site-packages/googleapiclient/discovery_cache/file_cache.py\", line 41, in <module>\n",
      "    'file_cache is unavailable when using oauth2client >= 4.0.0 or google-auth')\n",
      "ImportError: file_cache is unavailable when using oauth2client >= 4.0.0 or google-auth\n",
      "I0519 11:22:45.661129 140735859868544 discovery.py:271] URL being requested: GET https://earthengine.googleapis.com/$discovery/rest?version=v1alpha&prettyPrint=false\n",
      "W0519 11:22:47.844924 140735859868544 __init__.py:44] file_cache is unavailable when using oauth2client >= 4.0.0 or google-auth\n",
      "Traceback (most recent call last):\n",
      "  File \"/Users/ikersanchez/anaconda3/lib/python3.7/site-packages/googleapiclient/discovery_cache/__init__.py\", line 36, in autodetect\n",
      "    from google.appengine.api import memcache\n",
      "ModuleNotFoundError: No module named 'google.appengine'\n",
      "\n",
      "During handling of the above exception, another exception occurred:\n",
      "\n",
      "Traceback (most recent call last):\n",
      "  File \"/Users/ikersanchez/anaconda3/lib/python3.7/site-packages/googleapiclient/discovery_cache/file_cache.py\", line 33, in <module>\n",
      "    from oauth2client.contrib.locked_file import LockedFile\n",
      "ModuleNotFoundError: No module named 'oauth2client'\n",
      "\n",
      "During handling of the above exception, another exception occurred:\n",
      "\n",
      "Traceback (most recent call last):\n",
      "  File \"/Users/ikersanchez/anaconda3/lib/python3.7/site-packages/googleapiclient/discovery_cache/file_cache.py\", line 37, in <module>\n",
      "    from oauth2client.locked_file import LockedFile\n",
      "ModuleNotFoundError: No module named 'oauth2client'\n",
      "\n",
      "During handling of the above exception, another exception occurred:\n",
      "\n",
      "Traceback (most recent call last):\n",
      "  File \"/Users/ikersanchez/anaconda3/lib/python3.7/site-packages/googleapiclient/discovery_cache/__init__.py\", line 41, in autodetect\n",
      "    from . import file_cache\n",
      "  File \"/Users/ikersanchez/anaconda3/lib/python3.7/site-packages/googleapiclient/discovery_cache/file_cache.py\", line 41, in <module>\n",
      "    'file_cache is unavailable when using oauth2client >= 4.0.0 or google-auth')\n",
      "ImportError: file_cache is unavailable when using oauth2client >= 4.0.0 or google-auth\n",
      "I0519 11:22:47.845285 140735859868544 discovery.py:271] URL being requested: GET https://earthengine.googleapis.com/$discovery/rest?version=v1alpha&prettyPrint=false\n",
      "I0519 11:22:48.634880 140735859868544 discovery.py:867] URL being requested: GET https://earthengine.googleapis.com/v1alpha/projects/earthengine-legacy/algorithms?prettyPrint=false&alt=json\n",
      "I0519 11:22:49.931335 140735859868544 discovery.py:867] URL being requested: POST https://earthengine.googleapis.com/v1alpha/projects/earthengine-legacy/image:import?alt=json\n",
      "Started upload task with ID: 5MIW4RTXUUUTSRSSPJ6P57PI\n",
      "Running command using Cloud API.  Set --no-use_cloud_api to go back to using the API\n",
      "\n",
      "W0519 11:22:54.051000 140735859868544 __init__.py:44] file_cache is unavailable when using oauth2client >= 4.0.0 or google-auth\n",
      "Traceback (most recent call last):\n",
      "  File \"/Users/ikersanchez/anaconda3/lib/python3.7/site-packages/googleapiclient/discovery_cache/__init__.py\", line 36, in autodetect\n",
      "    from google.appengine.api import memcache\n",
      "ModuleNotFoundError: No module named 'google.appengine'\n",
      "\n",
      "During handling of the above exception, another exception occurred:\n",
      "\n",
      "Traceback (most recent call last):\n",
      "  File \"/Users/ikersanchez/anaconda3/lib/python3.7/site-packages/googleapiclient/discovery_cache/file_cache.py\", line 33, in <module>\n",
      "    from oauth2client.contrib.locked_file import LockedFile\n",
      "ModuleNotFoundError: No module named 'oauth2client'\n",
      "\n",
      "During handling of the above exception, another exception occurred:\n",
      "\n",
      "Traceback (most recent call last):\n",
      "  File \"/Users/ikersanchez/anaconda3/lib/python3.7/site-packages/googleapiclient/discovery_cache/file_cache.py\", line 37, in <module>\n",
      "    from oauth2client.locked_file import LockedFile\n",
      "ModuleNotFoundError: No module named 'oauth2client'\n",
      "\n",
      "During handling of the above exception, another exception occurred:\n",
      "\n",
      "Traceback (most recent call last):\n",
      "  File \"/Users/ikersanchez/anaconda3/lib/python3.7/site-packages/googleapiclient/discovery_cache/__init__.py\", line 41, in autodetect\n",
      "    from . import file_cache\n",
      "  File \"/Users/ikersanchez/anaconda3/lib/python3.7/site-packages/googleapiclient/discovery_cache/file_cache.py\", line 41, in <module>\n",
      "    'file_cache is unavailable when using oauth2client >= 4.0.0 or google-auth')\n",
      "ImportError: file_cache is unavailable when using oauth2client >= 4.0.0 or google-auth\n",
      "I0519 11:22:54.051973 140735859868544 discovery.py:271] URL being requested: GET https://earthengine.googleapis.com/$discovery/rest?version=v1alpha&prettyPrint=false\n",
      "W0519 11:22:55.107604 140735859868544 __init__.py:44] file_cache is unavailable when using oauth2client >= 4.0.0 or google-auth\n",
      "Traceback (most recent call last):\n",
      "  File \"/Users/ikersanchez/anaconda3/lib/python3.7/site-packages/googleapiclient/discovery_cache/__init__.py\", line 36, in autodetect\n",
      "    from google.appengine.api import memcache\n",
      "ModuleNotFoundError: No module named 'google.appengine'\n",
      "\n",
      "During handling of the above exception, another exception occurred:\n",
      "\n",
      "Traceback (most recent call last):\n",
      "  File \"/Users/ikersanchez/anaconda3/lib/python3.7/site-packages/googleapiclient/discovery_cache/file_cache.py\", line 33, in <module>\n",
      "    from oauth2client.contrib.locked_file import LockedFile\n",
      "ModuleNotFoundError: No module named 'oauth2client'\n",
      "\n",
      "During handling of the above exception, another exception occurred:\n",
      "\n",
      "Traceback (most recent call last):\n",
      "  File \"/Users/ikersanchez/anaconda3/lib/python3.7/site-packages/googleapiclient/discovery_cache/file_cache.py\", line 37, in <module>\n",
      "    from oauth2client.locked_file import LockedFile\n",
      "ModuleNotFoundError: No module named 'oauth2client'\n",
      "\n",
      "During handling of the above exception, another exception occurred:\n",
      "\n",
      "Traceback (most recent call last):\n",
      "  File \"/Users/ikersanchez/anaconda3/lib/python3.7/site-packages/googleapiclient/discovery_cache/__init__.py\", line 41, in autodetect\n",
      "    from . import file_cache\n",
      "  File \"/Users/ikersanchez/anaconda3/lib/python3.7/site-packages/googleapiclient/discovery_cache/file_cache.py\", line 41, in <module>\n",
      "    'file_cache is unavailable when using oauth2client >= 4.0.0 or google-auth')\n",
      "ImportError: file_cache is unavailable when using oauth2client >= 4.0.0 or google-auth\n",
      "I0519 11:22:55.107996 140735859868544 discovery.py:271] URL being requested: GET https://earthengine.googleapis.com/$discovery/rest?version=v1alpha&prettyPrint=false\n",
      "I0519 11:22:55.904809 140735859868544 discovery.py:867] URL being requested: GET https://earthengine.googleapis.com/v1alpha/projects/earthengine-legacy/algorithms?prettyPrint=false&alt=json\n",
      "I0519 11:22:56.622635 140735859868544 discovery.py:867] URL being requested: POST https://earthengine.googleapis.com/v1alpha/projects/earthengine-legacy/image:import?alt=json\n",
      "Started upload task with ID: YPXG6Z6TFUV66R7CPR23VTFL\n",
      "Running command using Cloud API.  Set --no-use_cloud_api to go back to using the API\n",
      "\n",
      "W0519 11:22:59.748394 140735859868544 __init__.py:44] file_cache is unavailable when using oauth2client >= 4.0.0 or google-auth\n",
      "Traceback (most recent call last):\n",
      "  File \"/Users/ikersanchez/anaconda3/lib/python3.7/site-packages/googleapiclient/discovery_cache/__init__.py\", line 36, in autodetect\n",
      "    from google.appengine.api import memcache\n",
      "ModuleNotFoundError: No module named 'google.appengine'\n",
      "\n",
      "During handling of the above exception, another exception occurred:\n",
      "\n",
      "Traceback (most recent call last):\n",
      "  File \"/Users/ikersanchez/anaconda3/lib/python3.7/site-packages/googleapiclient/discovery_cache/file_cache.py\", line 33, in <module>\n",
      "    from oauth2client.contrib.locked_file import LockedFile\n",
      "ModuleNotFoundError: No module named 'oauth2client'\n",
      "\n",
      "During handling of the above exception, another exception occurred:\n",
      "\n",
      "Traceback (most recent call last):\n",
      "  File \"/Users/ikersanchez/anaconda3/lib/python3.7/site-packages/googleapiclient/discovery_cache/file_cache.py\", line 37, in <module>\n",
      "    from oauth2client.locked_file import LockedFile\n",
      "ModuleNotFoundError: No module named 'oauth2client'\n",
      "\n",
      "During handling of the above exception, another exception occurred:\n",
      "\n",
      "Traceback (most recent call last):\n",
      "  File \"/Users/ikersanchez/anaconda3/lib/python3.7/site-packages/googleapiclient/discovery_cache/__init__.py\", line 41, in autodetect\n",
      "    from . import file_cache\n",
      "  File \"/Users/ikersanchez/anaconda3/lib/python3.7/site-packages/googleapiclient/discovery_cache/file_cache.py\", line 41, in <module>\n",
      "    'file_cache is unavailable when using oauth2client >= 4.0.0 or google-auth')\n",
      "ImportError: file_cache is unavailable when using oauth2client >= 4.0.0 or google-auth\n",
      "I0519 11:22:59.749053 140735859868544 discovery.py:271] URL being requested: GET https://earthengine.googleapis.com/$discovery/rest?version=v1alpha&prettyPrint=false\n",
      "W0519 11:23:00.842500 140735859868544 __init__.py:44] file_cache is unavailable when using oauth2client >= 4.0.0 or google-auth\n",
      "Traceback (most recent call last):\n",
      "  File \"/Users/ikersanchez/anaconda3/lib/python3.7/site-packages/googleapiclient/discovery_cache/__init__.py\", line 36, in autodetect\n",
      "    from google.appengine.api import memcache\n",
      "ModuleNotFoundError: No module named 'google.appengine'\n",
      "\n",
      "During handling of the above exception, another exception occurred:\n",
      "\n",
      "Traceback (most recent call last):\n",
      "  File \"/Users/ikersanchez/anaconda3/lib/python3.7/site-packages/googleapiclient/discovery_cache/file_cache.py\", line 33, in <module>\n",
      "    from oauth2client.contrib.locked_file import LockedFile\n",
      "ModuleNotFoundError: No module named 'oauth2client'\n",
      "\n",
      "During handling of the above exception, another exception occurred:\n",
      "\n",
      "Traceback (most recent call last):\n",
      "  File \"/Users/ikersanchez/anaconda3/lib/python3.7/site-packages/googleapiclient/discovery_cache/file_cache.py\", line 37, in <module>\n",
      "    from oauth2client.locked_file import LockedFile\n",
      "ModuleNotFoundError: No module named 'oauth2client'\n",
      "\n",
      "During handling of the above exception, another exception occurred:\n",
      "\n",
      "Traceback (most recent call last):\n",
      "  File \"/Users/ikersanchez/anaconda3/lib/python3.7/site-packages/googleapiclient/discovery_cache/__init__.py\", line 41, in autodetect\n",
      "    from . import file_cache\n",
      "  File \"/Users/ikersanchez/anaconda3/lib/python3.7/site-packages/googleapiclient/discovery_cache/file_cache.py\", line 41, in <module>\n",
      "    'file_cache is unavailable when using oauth2client >= 4.0.0 or google-auth')\n",
      "ImportError: file_cache is unavailable when using oauth2client >= 4.0.0 or google-auth\n",
      "I0519 11:23:00.843080 140735859868544 discovery.py:271] URL being requested: GET https://earthengine.googleapis.com/$discovery/rest?version=v1alpha&prettyPrint=false\n",
      "I0519 11:23:01.764616 140735859868544 discovery.py:867] URL being requested: GET https://earthengine.googleapis.com/v1alpha/projects/earthengine-legacy/algorithms?prettyPrint=false&alt=json\n",
      "I0519 11:23:02.844788 140735859868544 discovery.py:867] URL being requested: POST https://earthengine.googleapis.com/v1alpha/projects/earthengine-legacy/image:import?alt=json\n",
      "Started upload task with ID: DLNAGN3FYUEAMFBQURCWZ4AN\n",
      "Running command using Cloud API.  Set --no-use_cloud_api to go back to using the API\n",
      "\n",
      "W0519 11:23:06.214164 140735859868544 __init__.py:44] file_cache is unavailable when using oauth2client >= 4.0.0 or google-auth\n",
      "Traceback (most recent call last):\n",
      "  File \"/Users/ikersanchez/anaconda3/lib/python3.7/site-packages/googleapiclient/discovery_cache/__init__.py\", line 36, in autodetect\n",
      "    from google.appengine.api import memcache\n",
      "ModuleNotFoundError: No module named 'google.appengine'\n",
      "\n",
      "During handling of the above exception, another exception occurred:\n",
      "\n",
      "Traceback (most recent call last):\n",
      "  File \"/Users/ikersanchez/anaconda3/lib/python3.7/site-packages/googleapiclient/discovery_cache/file_cache.py\", line 33, in <module>\n",
      "    from oauth2client.contrib.locked_file import LockedFile\n",
      "ModuleNotFoundError: No module named 'oauth2client'\n",
      "\n",
      "During handling of the above exception, another exception occurred:\n",
      "\n",
      "Traceback (most recent call last):\n",
      "  File \"/Users/ikersanchez/anaconda3/lib/python3.7/site-packages/googleapiclient/discovery_cache/file_cache.py\", line 37, in <module>\n",
      "    from oauth2client.locked_file import LockedFile\n",
      "ModuleNotFoundError: No module named 'oauth2client'\n",
      "\n",
      "During handling of the above exception, another exception occurred:\n",
      "\n",
      "Traceback (most recent call last):\n",
      "  File \"/Users/ikersanchez/anaconda3/lib/python3.7/site-packages/googleapiclient/discovery_cache/__init__.py\", line 41, in autodetect\n",
      "    from . import file_cache\n",
      "  File \"/Users/ikersanchez/anaconda3/lib/python3.7/site-packages/googleapiclient/discovery_cache/file_cache.py\", line 41, in <module>\n",
      "    'file_cache is unavailable when using oauth2client >= 4.0.0 or google-auth')\n",
      "ImportError: file_cache is unavailable when using oauth2client >= 4.0.0 or google-auth\n",
      "I0519 11:23:06.214807 140735859868544 discovery.py:271] URL being requested: GET https://earthengine.googleapis.com/$discovery/rest?version=v1alpha&prettyPrint=false\n",
      "W0519 11:23:07.263700 140735859868544 __init__.py:44] file_cache is unavailable when using oauth2client >= 4.0.0 or google-auth\n",
      "Traceback (most recent call last):\n",
      "  File \"/Users/ikersanchez/anaconda3/lib/python3.7/site-packages/googleapiclient/discovery_cache/__init__.py\", line 36, in autodetect\n",
      "    from google.appengine.api import memcache\n",
      "ModuleNotFoundError: No module named 'google.appengine'\n",
      "\n",
      "During handling of the above exception, another exception occurred:\n",
      "\n",
      "Traceback (most recent call last):\n",
      "  File \"/Users/ikersanchez/anaconda3/lib/python3.7/site-packages/googleapiclient/discovery_cache/file_cache.py\", line 33, in <module>\n",
      "    from oauth2client.contrib.locked_file import LockedFile\n",
      "ModuleNotFoundError: No module named 'oauth2client'\n",
      "\n",
      "During handling of the above exception, another exception occurred:\n",
      "\n",
      "Traceback (most recent call last):\n",
      "  File \"/Users/ikersanchez/anaconda3/lib/python3.7/site-packages/googleapiclient/discovery_cache/file_cache.py\", line 37, in <module>\n",
      "    from oauth2client.locked_file import LockedFile\n",
      "ModuleNotFoundError: No module named 'oauth2client'\n",
      "\n",
      "During handling of the above exception, another exception occurred:\n",
      "\n",
      "Traceback (most recent call last):\n",
      "  File \"/Users/ikersanchez/anaconda3/lib/python3.7/site-packages/googleapiclient/discovery_cache/__init__.py\", line 41, in autodetect\n",
      "    from . import file_cache\n",
      "  File \"/Users/ikersanchez/anaconda3/lib/python3.7/site-packages/googleapiclient/discovery_cache/file_cache.py\", line 41, in <module>\n",
      "    'file_cache is unavailable when using oauth2client >= 4.0.0 or google-auth')\n",
      "ImportError: file_cache is unavailable when using oauth2client >= 4.0.0 or google-auth\n",
      "I0519 11:23:07.264089 140735859868544 discovery.py:271] URL being requested: GET https://earthengine.googleapis.com/$discovery/rest?version=v1alpha&prettyPrint=false\n",
      "I0519 11:23:08.617997 140735859868544 discovery.py:867] URL being requested: GET https://earthengine.googleapis.com/v1alpha/projects/earthengine-legacy/algorithms?prettyPrint=false&alt=json\n",
      "I0519 11:23:09.680770 140735859868544 discovery.py:867] URL being requested: POST https://earthengine.googleapis.com/v1alpha/projects/earthengine-legacy/image:import?alt=json\n",
      "Started upload task with ID: HQ6HFTZ6GEAJR2LF2B5HOKM6\n",
      "Running command using Cloud API.  Set --no-use_cloud_api to go back to using the API\n",
      "\n",
      "W0519 11:23:12.723857 140735859868544 __init__.py:44] file_cache is unavailable when using oauth2client >= 4.0.0 or google-auth\n",
      "Traceback (most recent call last):\n",
      "  File \"/Users/ikersanchez/anaconda3/lib/python3.7/site-packages/googleapiclient/discovery_cache/__init__.py\", line 36, in autodetect\n",
      "    from google.appengine.api import memcache\n",
      "ModuleNotFoundError: No module named 'google.appengine'\n",
      "\n",
      "During handling of the above exception, another exception occurred:\n",
      "\n",
      "Traceback (most recent call last):\n",
      "  File \"/Users/ikersanchez/anaconda3/lib/python3.7/site-packages/googleapiclient/discovery_cache/file_cache.py\", line 33, in <module>\n",
      "    from oauth2client.contrib.locked_file import LockedFile\n",
      "ModuleNotFoundError: No module named 'oauth2client'\n",
      "\n",
      "During handling of the above exception, another exception occurred:\n",
      "\n",
      "Traceback (most recent call last):\n",
      "  File \"/Users/ikersanchez/anaconda3/lib/python3.7/site-packages/googleapiclient/discovery_cache/file_cache.py\", line 37, in <module>\n",
      "    from oauth2client.locked_file import LockedFile\n",
      "ModuleNotFoundError: No module named 'oauth2client'\n",
      "\n",
      "During handling of the above exception, another exception occurred:\n",
      "\n",
      "Traceback (most recent call last):\n",
      "  File \"/Users/ikersanchez/anaconda3/lib/python3.7/site-packages/googleapiclient/discovery_cache/__init__.py\", line 41, in autodetect\n",
      "    from . import file_cache\n",
      "  File \"/Users/ikersanchez/anaconda3/lib/python3.7/site-packages/googleapiclient/discovery_cache/file_cache.py\", line 41, in <module>\n",
      "    'file_cache is unavailable when using oauth2client >= 4.0.0 or google-auth')\n",
      "ImportError: file_cache is unavailable when using oauth2client >= 4.0.0 or google-auth\n",
      "I0519 11:23:12.724667 140735859868544 discovery.py:271] URL being requested: GET https://earthengine.googleapis.com/$discovery/rest?version=v1alpha&prettyPrint=false\n",
      "W0519 11:23:13.636933 140735859868544 __init__.py:44] file_cache is unavailable when using oauth2client >= 4.0.0 or google-auth\n",
      "Traceback (most recent call last):\n",
      "  File \"/Users/ikersanchez/anaconda3/lib/python3.7/site-packages/googleapiclient/discovery_cache/__init__.py\", line 36, in autodetect\n",
      "    from google.appengine.api import memcache\n",
      "ModuleNotFoundError: No module named 'google.appengine'\n",
      "\n",
      "During handling of the above exception, another exception occurred:\n",
      "\n",
      "Traceback (most recent call last):\n",
      "  File \"/Users/ikersanchez/anaconda3/lib/python3.7/site-packages/googleapiclient/discovery_cache/file_cache.py\", line 33, in <module>\n",
      "    from oauth2client.contrib.locked_file import LockedFile\n",
      "ModuleNotFoundError: No module named 'oauth2client'\n",
      "\n",
      "During handling of the above exception, another exception occurred:\n",
      "\n",
      "Traceback (most recent call last):\n",
      "  File \"/Users/ikersanchez/anaconda3/lib/python3.7/site-packages/googleapiclient/discovery_cache/file_cache.py\", line 37, in <module>\n",
      "    from oauth2client.locked_file import LockedFile\n",
      "ModuleNotFoundError: No module named 'oauth2client'\n",
      "\n",
      "During handling of the above exception, another exception occurred:\n",
      "\n",
      "Traceback (most recent call last):\n",
      "  File \"/Users/ikersanchez/anaconda3/lib/python3.7/site-packages/googleapiclient/discovery_cache/__init__.py\", line 41, in autodetect\n",
      "    from . import file_cache\n",
      "  File \"/Users/ikersanchez/anaconda3/lib/python3.7/site-packages/googleapiclient/discovery_cache/file_cache.py\", line 41, in <module>\n",
      "    'file_cache is unavailable when using oauth2client >= 4.0.0 or google-auth')\n",
      "ImportError: file_cache is unavailable when using oauth2client >= 4.0.0 or google-auth\n",
      "I0519 11:23:13.640902 140735859868544 discovery.py:271] URL being requested: GET https://earthengine.googleapis.com/$discovery/rest?version=v1alpha&prettyPrint=false\n",
      "I0519 11:23:16.926495 140735859868544 discovery.py:867] URL being requested: GET https://earthengine.googleapis.com/v1alpha/projects/earthengine-legacy/algorithms?prettyPrint=false&alt=json\n",
      "I0519 11:23:18.189321 140735859868544 discovery.py:867] URL being requested: POST https://earthengine.googleapis.com/v1alpha/projects/earthengine-legacy/image:import?alt=json\n",
      "Started upload task with ID: RY7PRH7JIZPLFILQJEXAS5KZ\n",
      "Running command using Cloud API.  Set --no-use_cloud_api to go back to using the API\n",
      "\n",
      "W0519 11:23:22.010650 140735859868544 __init__.py:44] file_cache is unavailable when using oauth2client >= 4.0.0 or google-auth\n",
      "Traceback (most recent call last):\n",
      "  File \"/Users/ikersanchez/anaconda3/lib/python3.7/site-packages/googleapiclient/discovery_cache/__init__.py\", line 36, in autodetect\n",
      "    from google.appengine.api import memcache\n",
      "ModuleNotFoundError: No module named 'google.appengine'\n",
      "\n",
      "During handling of the above exception, another exception occurred:\n",
      "\n",
      "Traceback (most recent call last):\n",
      "  File \"/Users/ikersanchez/anaconda3/lib/python3.7/site-packages/googleapiclient/discovery_cache/file_cache.py\", line 33, in <module>\n",
      "    from oauth2client.contrib.locked_file import LockedFile\n",
      "ModuleNotFoundError: No module named 'oauth2client'\n",
      "\n",
      "During handling of the above exception, another exception occurred:\n",
      "\n",
      "Traceback (most recent call last):\n",
      "  File \"/Users/ikersanchez/anaconda3/lib/python3.7/site-packages/googleapiclient/discovery_cache/file_cache.py\", line 37, in <module>\n",
      "    from oauth2client.locked_file import LockedFile\n",
      "ModuleNotFoundError: No module named 'oauth2client'\n",
      "\n",
      "During handling of the above exception, another exception occurred:\n",
      "\n",
      "Traceback (most recent call last):\n",
      "  File \"/Users/ikersanchez/anaconda3/lib/python3.7/site-packages/googleapiclient/discovery_cache/__init__.py\", line 41, in autodetect\n",
      "    from . import file_cache\n",
      "  File \"/Users/ikersanchez/anaconda3/lib/python3.7/site-packages/googleapiclient/discovery_cache/file_cache.py\", line 41, in <module>\n",
      "    'file_cache is unavailable when using oauth2client >= 4.0.0 or google-auth')\n",
      "ImportError: file_cache is unavailable when using oauth2client >= 4.0.0 or google-auth\n",
      "I0519 11:23:22.011543 140735859868544 discovery.py:271] URL being requested: GET https://earthengine.googleapis.com/$discovery/rest?version=v1alpha&prettyPrint=false\n",
      "W0519 11:23:23.634458 140735859868544 __init__.py:44] file_cache is unavailable when using oauth2client >= 4.0.0 or google-auth\n",
      "Traceback (most recent call last):\n",
      "  File \"/Users/ikersanchez/anaconda3/lib/python3.7/site-packages/googleapiclient/discovery_cache/__init__.py\", line 36, in autodetect\n",
      "    from google.appengine.api import memcache\n",
      "ModuleNotFoundError: No module named 'google.appengine'\n",
      "\n",
      "During handling of the above exception, another exception occurred:\n",
      "\n",
      "Traceback (most recent call last):\n",
      "  File \"/Users/ikersanchez/anaconda3/lib/python3.7/site-packages/googleapiclient/discovery_cache/file_cache.py\", line 33, in <module>\n",
      "    from oauth2client.contrib.locked_file import LockedFile\n",
      "ModuleNotFoundError: No module named 'oauth2client'\n",
      "\n",
      "During handling of the above exception, another exception occurred:\n",
      "\n",
      "Traceback (most recent call last):\n",
      "  File \"/Users/ikersanchez/anaconda3/lib/python3.7/site-packages/googleapiclient/discovery_cache/file_cache.py\", line 37, in <module>\n",
      "    from oauth2client.locked_file import LockedFile\n",
      "ModuleNotFoundError: No module named 'oauth2client'\n",
      "\n",
      "During handling of the above exception, another exception occurred:\n",
      "\n",
      "Traceback (most recent call last):\n",
      "  File \"/Users/ikersanchez/anaconda3/lib/python3.7/site-packages/googleapiclient/discovery_cache/__init__.py\", line 41, in autodetect\n",
      "    from . import file_cache\n",
      "  File \"/Users/ikersanchez/anaconda3/lib/python3.7/site-packages/googleapiclient/discovery_cache/file_cache.py\", line 41, in <module>\n",
      "    'file_cache is unavailable when using oauth2client >= 4.0.0 or google-auth')\n",
      "ImportError: file_cache is unavailable when using oauth2client >= 4.0.0 or google-auth\n",
      "I0519 11:23:23.634821 140735859868544 discovery.py:271] URL being requested: GET https://earthengine.googleapis.com/$discovery/rest?version=v1alpha&prettyPrint=false\n",
      "I0519 11:23:25.238360 140735859868544 discovery.py:867] URL being requested: GET https://earthengine.googleapis.com/v1alpha/projects/earthengine-legacy/algorithms?prettyPrint=false&alt=json\n",
      "I0519 11:23:25.831088 140735859868544 discovery.py:867] URL being requested: POST https://earthengine.googleapis.com/v1alpha/projects/earthengine-legacy/image:import?alt=json\n",
      "Started upload task with ID: RQPXH3UEL52YTLR6PURGR6LT\n",
      "Running command using Cloud API.  Set --no-use_cloud_api to go back to using the API\n",
      "\n",
      "W0519 11:23:29.434327 140735859868544 __init__.py:44] file_cache is unavailable when using oauth2client >= 4.0.0 or google-auth\n",
      "Traceback (most recent call last):\n",
      "  File \"/Users/ikersanchez/anaconda3/lib/python3.7/site-packages/googleapiclient/discovery_cache/__init__.py\", line 36, in autodetect\n",
      "    from google.appengine.api import memcache\n",
      "ModuleNotFoundError: No module named 'google.appengine'\n",
      "\n",
      "During handling of the above exception, another exception occurred:\n",
      "\n",
      "Traceback (most recent call last):\n",
      "  File \"/Users/ikersanchez/anaconda3/lib/python3.7/site-packages/googleapiclient/discovery_cache/file_cache.py\", line 33, in <module>\n",
      "    from oauth2client.contrib.locked_file import LockedFile\n",
      "ModuleNotFoundError: No module named 'oauth2client'\n",
      "\n",
      "During handling of the above exception, another exception occurred:\n",
      "\n",
      "Traceback (most recent call last):\n",
      "  File \"/Users/ikersanchez/anaconda3/lib/python3.7/site-packages/googleapiclient/discovery_cache/file_cache.py\", line 37, in <module>\n",
      "    from oauth2client.locked_file import LockedFile\n",
      "ModuleNotFoundError: No module named 'oauth2client'\n",
      "\n",
      "During handling of the above exception, another exception occurred:\n",
      "\n",
      "Traceback (most recent call last):\n",
      "  File \"/Users/ikersanchez/anaconda3/lib/python3.7/site-packages/googleapiclient/discovery_cache/__init__.py\", line 41, in autodetect\n",
      "    from . import file_cache\n",
      "  File \"/Users/ikersanchez/anaconda3/lib/python3.7/site-packages/googleapiclient/discovery_cache/file_cache.py\", line 41, in <module>\n",
      "    'file_cache is unavailable when using oauth2client >= 4.0.0 or google-auth')\n",
      "ImportError: file_cache is unavailable when using oauth2client >= 4.0.0 or google-auth\n",
      "I0519 11:23:29.434853 140735859868544 discovery.py:271] URL being requested: GET https://earthengine.googleapis.com/$discovery/rest?version=v1alpha&prettyPrint=false\n",
      "W0519 11:23:30.499421 140735859868544 __init__.py:44] file_cache is unavailable when using oauth2client >= 4.0.0 or google-auth\n",
      "Traceback (most recent call last):\n",
      "  File \"/Users/ikersanchez/anaconda3/lib/python3.7/site-packages/googleapiclient/discovery_cache/__init__.py\", line 36, in autodetect\n",
      "    from google.appengine.api import memcache\n",
      "ModuleNotFoundError: No module named 'google.appengine'\n",
      "\n",
      "During handling of the above exception, another exception occurred:\n",
      "\n",
      "Traceback (most recent call last):\n",
      "  File \"/Users/ikersanchez/anaconda3/lib/python3.7/site-packages/googleapiclient/discovery_cache/file_cache.py\", line 33, in <module>\n",
      "    from oauth2client.contrib.locked_file import LockedFile\n",
      "ModuleNotFoundError: No module named 'oauth2client'\n",
      "\n",
      "During handling of the above exception, another exception occurred:\n",
      "\n",
      "Traceback (most recent call last):\n",
      "  File \"/Users/ikersanchez/anaconda3/lib/python3.7/site-packages/googleapiclient/discovery_cache/file_cache.py\", line 37, in <module>\n",
      "    from oauth2client.locked_file import LockedFile\n",
      "ModuleNotFoundError: No module named 'oauth2client'\n",
      "\n",
      "During handling of the above exception, another exception occurred:\n",
      "\n",
      "Traceback (most recent call last):\n",
      "  File \"/Users/ikersanchez/anaconda3/lib/python3.7/site-packages/googleapiclient/discovery_cache/__init__.py\", line 41, in autodetect\n",
      "    from . import file_cache\n",
      "  File \"/Users/ikersanchez/anaconda3/lib/python3.7/site-packages/googleapiclient/discovery_cache/file_cache.py\", line 41, in <module>\n",
      "    'file_cache is unavailable when using oauth2client >= 4.0.0 or google-auth')\n",
      "ImportError: file_cache is unavailable when using oauth2client >= 4.0.0 or google-auth\n",
      "I0519 11:23:30.499850 140735859868544 discovery.py:271] URL being requested: GET https://earthengine.googleapis.com/$discovery/rest?version=v1alpha&prettyPrint=false\n",
      "I0519 11:23:31.709703 140735859868544 discovery.py:867] URL being requested: GET https://earthengine.googleapis.com/v1alpha/projects/earthengine-legacy/algorithms?prettyPrint=false&alt=json\n",
      "I0519 11:23:32.368780 140735859868544 discovery.py:867] URL being requested: POST https://earthengine.googleapis.com/v1alpha/projects/earthengine-legacy/image:import?alt=json\n",
      "Started upload task with ID: 4MT6OQJ3WOLWUJ2Z5NDAZPN2\n",
      "Running command using Cloud API.  Set --no-use_cloud_api to go back to using the API\n",
      "\n",
      "W0519 11:23:35.390493 140735859868544 __init__.py:44] file_cache is unavailable when using oauth2client >= 4.0.0 or google-auth\n",
      "Traceback (most recent call last):\n",
      "  File \"/Users/ikersanchez/anaconda3/lib/python3.7/site-packages/googleapiclient/discovery_cache/__init__.py\", line 36, in autodetect\n",
      "    from google.appengine.api import memcache\n",
      "ModuleNotFoundError: No module named 'google.appengine'\n",
      "\n",
      "During handling of the above exception, another exception occurred:\n",
      "\n",
      "Traceback (most recent call last):\n",
      "  File \"/Users/ikersanchez/anaconda3/lib/python3.7/site-packages/googleapiclient/discovery_cache/file_cache.py\", line 33, in <module>\n",
      "    from oauth2client.contrib.locked_file import LockedFile\n",
      "ModuleNotFoundError: No module named 'oauth2client'\n",
      "\n",
      "During handling of the above exception, another exception occurred:\n",
      "\n",
      "Traceback (most recent call last):\n",
      "  File \"/Users/ikersanchez/anaconda3/lib/python3.7/site-packages/googleapiclient/discovery_cache/file_cache.py\", line 37, in <module>\n",
      "    from oauth2client.locked_file import LockedFile\n",
      "ModuleNotFoundError: No module named 'oauth2client'\n",
      "\n",
      "During handling of the above exception, another exception occurred:\n",
      "\n",
      "Traceback (most recent call last):\n",
      "  File \"/Users/ikersanchez/anaconda3/lib/python3.7/site-packages/googleapiclient/discovery_cache/__init__.py\", line 41, in autodetect\n",
      "    from . import file_cache\n",
      "  File \"/Users/ikersanchez/anaconda3/lib/python3.7/site-packages/googleapiclient/discovery_cache/file_cache.py\", line 41, in <module>\n",
      "    'file_cache is unavailable when using oauth2client >= 4.0.0 or google-auth')\n",
      "ImportError: file_cache is unavailable when using oauth2client >= 4.0.0 or google-auth\n",
      "I0519 11:23:35.391169 140735859868544 discovery.py:271] URL being requested: GET https://earthengine.googleapis.com/$discovery/rest?version=v1alpha&prettyPrint=false\n",
      "W0519 11:23:36.312337 140735859868544 __init__.py:44] file_cache is unavailable when using oauth2client >= 4.0.0 or google-auth\n",
      "Traceback (most recent call last):\n",
      "  File \"/Users/ikersanchez/anaconda3/lib/python3.7/site-packages/googleapiclient/discovery_cache/__init__.py\", line 36, in autodetect\n",
      "    from google.appengine.api import memcache\n",
      "ModuleNotFoundError: No module named 'google.appengine'\n",
      "\n",
      "During handling of the above exception, another exception occurred:\n",
      "\n",
      "Traceback (most recent call last):\n",
      "  File \"/Users/ikersanchez/anaconda3/lib/python3.7/site-packages/googleapiclient/discovery_cache/file_cache.py\", line 33, in <module>\n",
      "    from oauth2client.contrib.locked_file import LockedFile\n",
      "ModuleNotFoundError: No module named 'oauth2client'\n",
      "\n",
      "During handling of the above exception, another exception occurred:\n",
      "\n",
      "Traceback (most recent call last):\n",
      "  File \"/Users/ikersanchez/anaconda3/lib/python3.7/site-packages/googleapiclient/discovery_cache/file_cache.py\", line 37, in <module>\n",
      "    from oauth2client.locked_file import LockedFile\n",
      "ModuleNotFoundError: No module named 'oauth2client'\n",
      "\n",
      "During handling of the above exception, another exception occurred:\n",
      "\n",
      "Traceback (most recent call last):\n",
      "  File \"/Users/ikersanchez/anaconda3/lib/python3.7/site-packages/googleapiclient/discovery_cache/__init__.py\", line 41, in autodetect\n",
      "    from . import file_cache\n",
      "  File \"/Users/ikersanchez/anaconda3/lib/python3.7/site-packages/googleapiclient/discovery_cache/file_cache.py\", line 41, in <module>\n",
      "    'file_cache is unavailable when using oauth2client >= 4.0.0 or google-auth')\n",
      "ImportError: file_cache is unavailable when using oauth2client >= 4.0.0 or google-auth\n",
      "I0519 11:23:36.312705 140735859868544 discovery.py:271] URL being requested: GET https://earthengine.googleapis.com/$discovery/rest?version=v1alpha&prettyPrint=false\n",
      "I0519 11:23:37.117542 140735859868544 discovery.py:867] URL being requested: GET https://earthengine.googleapis.com/v1alpha/projects/earthengine-legacy/algorithms?prettyPrint=false&alt=json\n",
      "I0519 11:23:37.716182 140735859868544 discovery.py:867] URL being requested: POST https://earthengine.googleapis.com/v1alpha/projects/earthengine-legacy/image:import?alt=json\n",
      "Started upload task with ID: KNUCHFOBBRS4EBEWXAKUFP7C\n",
      "Running command using Cloud API.  Set --no-use_cloud_api to go back to using the API\n",
      "\n",
      "W0519 11:23:41.509368 140735859868544 __init__.py:44] file_cache is unavailable when using oauth2client >= 4.0.0 or google-auth\n",
      "Traceback (most recent call last):\n",
      "  File \"/Users/ikersanchez/anaconda3/lib/python3.7/site-packages/googleapiclient/discovery_cache/__init__.py\", line 36, in autodetect\n",
      "    from google.appengine.api import memcache\n",
      "ModuleNotFoundError: No module named 'google.appengine'\n",
      "\n",
      "During handling of the above exception, another exception occurred:\n",
      "\n",
      "Traceback (most recent call last):\n",
      "  File \"/Users/ikersanchez/anaconda3/lib/python3.7/site-packages/googleapiclient/discovery_cache/file_cache.py\", line 33, in <module>\n",
      "    from oauth2client.contrib.locked_file import LockedFile\n",
      "ModuleNotFoundError: No module named 'oauth2client'\n",
      "\n",
      "During handling of the above exception, another exception occurred:\n",
      "\n",
      "Traceback (most recent call last):\n",
      "  File \"/Users/ikersanchez/anaconda3/lib/python3.7/site-packages/googleapiclient/discovery_cache/file_cache.py\", line 37, in <module>\n",
      "    from oauth2client.locked_file import LockedFile\n",
      "ModuleNotFoundError: No module named 'oauth2client'\n",
      "\n",
      "During handling of the above exception, another exception occurred:\n",
      "\n",
      "Traceback (most recent call last):\n",
      "  File \"/Users/ikersanchez/anaconda3/lib/python3.7/site-packages/googleapiclient/discovery_cache/__init__.py\", line 41, in autodetect\n",
      "    from . import file_cache\n",
      "  File \"/Users/ikersanchez/anaconda3/lib/python3.7/site-packages/googleapiclient/discovery_cache/file_cache.py\", line 41, in <module>\n",
      "    'file_cache is unavailable when using oauth2client >= 4.0.0 or google-auth')\n",
      "ImportError: file_cache is unavailable when using oauth2client >= 4.0.0 or google-auth\n",
      "I0519 11:23:41.509913 140735859868544 discovery.py:271] URL being requested: GET https://earthengine.googleapis.com/$discovery/rest?version=v1alpha&prettyPrint=false\n",
      "W0519 11:23:42.467819 140735859868544 __init__.py:44] file_cache is unavailable when using oauth2client >= 4.0.0 or google-auth\n",
      "Traceback (most recent call last):\n",
      "  File \"/Users/ikersanchez/anaconda3/lib/python3.7/site-packages/googleapiclient/discovery_cache/__init__.py\", line 36, in autodetect\n",
      "    from google.appengine.api import memcache\n",
      "ModuleNotFoundError: No module named 'google.appengine'\n",
      "\n",
      "During handling of the above exception, another exception occurred:\n",
      "\n",
      "Traceback (most recent call last):\n",
      "  File \"/Users/ikersanchez/anaconda3/lib/python3.7/site-packages/googleapiclient/discovery_cache/file_cache.py\", line 33, in <module>\n",
      "    from oauth2client.contrib.locked_file import LockedFile\n",
      "ModuleNotFoundError: No module named 'oauth2client'\n",
      "\n",
      "During handling of the above exception, another exception occurred:\n",
      "\n",
      "Traceback (most recent call last):\n",
      "  File \"/Users/ikersanchez/anaconda3/lib/python3.7/site-packages/googleapiclient/discovery_cache/file_cache.py\", line 37, in <module>\n",
      "    from oauth2client.locked_file import LockedFile\n",
      "ModuleNotFoundError: No module named 'oauth2client'\n",
      "\n",
      "During handling of the above exception, another exception occurred:\n",
      "\n",
      "Traceback (most recent call last):\n",
      "  File \"/Users/ikersanchez/anaconda3/lib/python3.7/site-packages/googleapiclient/discovery_cache/__init__.py\", line 41, in autodetect\n",
      "    from . import file_cache\n",
      "  File \"/Users/ikersanchez/anaconda3/lib/python3.7/site-packages/googleapiclient/discovery_cache/file_cache.py\", line 41, in <module>\n",
      "    'file_cache is unavailable when using oauth2client >= 4.0.0 or google-auth')\n",
      "ImportError: file_cache is unavailable when using oauth2client >= 4.0.0 or google-auth\n",
      "I0519 11:23:42.476171 140735859868544 discovery.py:271] URL being requested: GET https://earthengine.googleapis.com/$discovery/rest?version=v1alpha&prettyPrint=false\n",
      "I0519 11:23:43.298085 140735859868544 discovery.py:867] URL being requested: GET https://earthengine.googleapis.com/v1alpha/projects/earthengine-legacy/algorithms?prettyPrint=false&alt=json\n",
      "I0519 11:23:44.544624 140735859868544 discovery.py:867] URL being requested: POST https://earthengine.googleapis.com/v1alpha/projects/earthengine-legacy/image:import?alt=json\n",
      "Started upload task with ID: X43GMCT37LNKTPEKV6KY46FS\n",
      "Running command using Cloud API.  Set --no-use_cloud_api to go back to using the API\n",
      "\n",
      "W0519 11:23:47.620219 140735859868544 __init__.py:44] file_cache is unavailable when using oauth2client >= 4.0.0 or google-auth\n",
      "Traceback (most recent call last):\n",
      "  File \"/Users/ikersanchez/anaconda3/lib/python3.7/site-packages/googleapiclient/discovery_cache/__init__.py\", line 36, in autodetect\n",
      "    from google.appengine.api import memcache\n",
      "ModuleNotFoundError: No module named 'google.appengine'\n",
      "\n",
      "During handling of the above exception, another exception occurred:\n",
      "\n",
      "Traceback (most recent call last):\n",
      "  File \"/Users/ikersanchez/anaconda3/lib/python3.7/site-packages/googleapiclient/discovery_cache/file_cache.py\", line 33, in <module>\n",
      "    from oauth2client.contrib.locked_file import LockedFile\n",
      "ModuleNotFoundError: No module named 'oauth2client'\n",
      "\n",
      "During handling of the above exception, another exception occurred:\n",
      "\n",
      "Traceback (most recent call last):\n",
      "  File \"/Users/ikersanchez/anaconda3/lib/python3.7/site-packages/googleapiclient/discovery_cache/file_cache.py\", line 37, in <module>\n",
      "    from oauth2client.locked_file import LockedFile\n",
      "ModuleNotFoundError: No module named 'oauth2client'\n",
      "\n",
      "During handling of the above exception, another exception occurred:\n",
      "\n",
      "Traceback (most recent call last):\n",
      "  File \"/Users/ikersanchez/anaconda3/lib/python3.7/site-packages/googleapiclient/discovery_cache/__init__.py\", line 41, in autodetect\n",
      "    from . import file_cache\n",
      "  File \"/Users/ikersanchez/anaconda3/lib/python3.7/site-packages/googleapiclient/discovery_cache/file_cache.py\", line 41, in <module>\n",
      "    'file_cache is unavailable when using oauth2client >= 4.0.0 or google-auth')\n",
      "ImportError: file_cache is unavailable when using oauth2client >= 4.0.0 or google-auth\n",
      "I0519 11:23:47.620765 140735859868544 discovery.py:271] URL being requested: GET https://earthengine.googleapis.com/$discovery/rest?version=v1alpha&prettyPrint=false\n",
      "W0519 11:23:48.531000 140735859868544 __init__.py:44] file_cache is unavailable when using oauth2client >= 4.0.0 or google-auth\n",
      "Traceback (most recent call last):\n",
      "  File \"/Users/ikersanchez/anaconda3/lib/python3.7/site-packages/googleapiclient/discovery_cache/__init__.py\", line 36, in autodetect\n",
      "    from google.appengine.api import memcache\n",
      "ModuleNotFoundError: No module named 'google.appengine'\n",
      "\n",
      "During handling of the above exception, another exception occurred:\n",
      "\n",
      "Traceback (most recent call last):\n",
      "  File \"/Users/ikersanchez/anaconda3/lib/python3.7/site-packages/googleapiclient/discovery_cache/file_cache.py\", line 33, in <module>\n",
      "    from oauth2client.contrib.locked_file import LockedFile\n",
      "ModuleNotFoundError: No module named 'oauth2client'\n",
      "\n",
      "During handling of the above exception, another exception occurred:\n",
      "\n",
      "Traceback (most recent call last):\n",
      "  File \"/Users/ikersanchez/anaconda3/lib/python3.7/site-packages/googleapiclient/discovery_cache/file_cache.py\", line 37, in <module>\n",
      "    from oauth2client.locked_file import LockedFile\n",
      "ModuleNotFoundError: No module named 'oauth2client'\n",
      "\n",
      "During handling of the above exception, another exception occurred:\n",
      "\n",
      "Traceback (most recent call last):\n",
      "  File \"/Users/ikersanchez/anaconda3/lib/python3.7/site-packages/googleapiclient/discovery_cache/__init__.py\", line 41, in autodetect\n",
      "    from . import file_cache\n",
      "  File \"/Users/ikersanchez/anaconda3/lib/python3.7/site-packages/googleapiclient/discovery_cache/file_cache.py\", line 41, in <module>\n",
      "    'file_cache is unavailable when using oauth2client >= 4.0.0 or google-auth')\n",
      "ImportError: file_cache is unavailable when using oauth2client >= 4.0.0 or google-auth\n",
      "I0519 11:23:48.531455 140735859868544 discovery.py:271] URL being requested: GET https://earthengine.googleapis.com/$discovery/rest?version=v1alpha&prettyPrint=false\n",
      "I0519 11:23:49.316735 140735859868544 discovery.py:867] URL being requested: GET https://earthengine.googleapis.com/v1alpha/projects/earthengine-legacy/algorithms?prettyPrint=false&alt=json\n",
      "I0519 11:23:50.570827 140735859868544 discovery.py:867] URL being requested: POST https://earthengine.googleapis.com/v1alpha/projects/earthengine-legacy/image:import?alt=json\n",
      "Started upload task with ID: 2OBNNWNOFKTF6BT5Z6E7TKAH\n"
     ]
    }
   ],
   "source": [
    "years = np.arange(2000, 2018+1, 1).astype(np.str)\n",
    "\n",
    "# We create a collection asset in Earth Engine to use as a write target.\n",
    "!earthengine create collection projects/soils-revealed/ESA_landcover_ipcc\n",
    "\n",
    "# Next, we use the upload image command to send individual images to the collection.\n",
    "for year in years:\n",
    "    !earthengine upload image --time_start {year}-01-01 --time_end {year}-12-31 --asset_id projects/soils-revealed/ESA_landcover_ipcc/ESA_{year}_ipcc --pyramiding_policy=sample gs://vizz-data-transfer/land-cover/ESA_{year}_ipcc.tif \n",
    "        \n",
    "        \n",
    "        "
   ]
  },
  {
   "cell_type": "markdown",
   "metadata": {},
   "source": [
    "### Export EE image to Asset"
   ]
  },
  {
   "cell_type": "code",
   "execution_count": 7,
   "metadata": {},
   "outputs": [],
   "source": [
    "import ee\n",
    "ee.Initialize()"
   ]
  },
  {
   "cell_type": "code",
   "execution_count": 12,
   "metadata": {},
   "outputs": [],
   "source": [
    "years = np.arange(1983, 2017+1, 1).astype(np.str)\n",
    "\n",
    "\n",
    "for year in years:\n",
    "    image = ee.Image(f'users/iker/SOC_maps/SOC_concentration_q50/SOC_{year}')\n",
    "    \n",
    "    task = ee.batch.Export.image.toAsset(\n",
    "        image = image,\n",
    "        description = 'imageToAsset',\n",
    "        assetId = f'projects/soils-revealed/experimental-dataset/SOC_concentration/SOC_concentration_{year}',\n",
    "        scale = 300,\n",
    "        pyramidingPolicy = {'b1': 'mean'},\n",
    "        maxPixels = 1e13)\n",
    "    task.start()"
   ]
  },
  {
   "cell_type": "code",
   "execution_count": 13,
   "metadata": {},
   "outputs": [],
   "source": [
    "assets = ['SOCS_0_200cm_year_2010AD_10km', 'SOCS_0_200cm_year_NoLU_10km']\n",
    "\n",
    "for asset in assets:\n",
    "    image = ee.Image(f'users/iker/SOC_maps/{asset}')\n",
    "    \n",
    "    task = ee.batch.Export.image.toAsset(\n",
    "        image = image,\n",
    "        description = 'imageToAsset',\n",
    "        assetId = f'projects/soils-revealed/Historic/{asset}',\n",
    "        scale = 300,\n",
    "        pyramidingPolicy = {'b1': 'mean'},\n",
    "        maxPixels = 1e13)\n",
    "    task.start()"
   ]
  },
  {
   "cell_type": "code",
   "execution_count": null,
   "metadata": {},
   "outputs": [],
   "source": []
  }
 ],
 "metadata": {
  "kernelspec": {
   "display_name": "Python 3",
   "language": "python",
   "name": "python3"
  },
  "language_info": {
   "codemirror_mode": {
    "name": "ipython",
    "version": 3
   },
   "file_extension": ".py",
   "mimetype": "text/x-python",
   "name": "python",
   "nbconvert_exporter": "python",
   "pygments_lexer": "ipython3",
   "version": "3.8.2"
  }
 },
 "nbformat": 4,
 "nbformat_minor": 4
}
